Workbook

Sheet Overall_MONTHLY_SALES
B2: Month | C2: Value IN Lacs | D2: In %
B3: JAN | C3: 238.00045 | D3: =C3/$C$15
B4: FEB | C4: 117.97586 | D4: =C4/$C$15
B5: MAR | D5: =C5/$C$15
B6: APR | D6: =C6/$C$15
B7: MAY | D7: =C7/$C$15
B8: JUN | D8: =C8/$C$15
B9: JUL | D9: =C9/$C$15
B10: AUG | D10: =C10/$C$15
B11: SEP | D11: =C11/$C$15
B12: OCT | D12: =C12/$C$15
B13: NOV | D13: =C13/$C$15
B14: DEC | D14: =C14/$C$15
B15: Total | C15: =SUM(C3:C14) | D15: =C15/$C$15

Sheet Categorywise_Variance
B2: IN Lacs. | C2: Budgeted | H2: Actual | M2: Variance | R2: Achivement IN %
B3: Monthly | C3: Export | D3: B2B | E3: B2C | F3: Total | H3: Export | I3: B2B | J3: B2C | K3: Total | M3: Export | N3: B2B | O3: B2C | P3: Total | R3: Export | S3: B2B | T3: B2C | U3: Total
B4: Jan | C4: 356.56715 | D4: 32.449246 | E4: 62.261034 | F4: =SUM(C4:E4) | H4: 134.46 | I4: 15.88 | J4: 87.66 | K4: =IF(H4="","",SUM(H4:J4)) | M4: =IF(H4="","",H4-C4) | N4: =IF(I4="","",I4-D4) | O4: =IF(J4="","",J4-E4) | P4: =IF(K4="","",K4-F4) | R4: =IF(H4="","",IFERROR(H4/C4,0)) | S4: =IF(I4="","",IFERROR(I4/D4,0)) | T4: =IF(J4="","",IFERROR(J4/E4,0)) | U4: =IF(K4="","",IFERROR(K4/F4,0))
B5: Feb | C5: 161.00696 | D5: 30.846285 | E5: 24.850228 | F5: =SUM(C5:E5) | H5: 45.38 | I5: 12.61 | J5: 59.98 | K5: =IF(H5="","",SUM(H5:J5)) | M5: =IF(H5="","",H5-C5) | N5: =IF(I5="","",I5-D5) | O5: =IF(J5="","",J5-E5) | P5: =IF(K5="","",K5-F5) | R5: =IF(H5="","",IFERROR(H5/C5,0)) | S5: =IF(I5="","",IFERROR(I5/D5,0)) | T5: =IF(J5="","",IFERROR(J5/E5,0)) | U5: =IF(K5="","",IFERROR(K5/F5,0))
B6: Mar | C6: 206.98984 | D6: 71.582307 | E6: 29.98435 | F6: =SUM(C6:E6) | H6: 106.6 | I6: 11.98 | J6: 120.26 | K6: =IF(H6="","",SUM(H6:J6)) | M6: =IF(H6="","",H6-C6) | N6: =IF(I6="","",I6-D6) | O6: =IF(J6="","",J6-E6) | P6: =IF(K6="","",K6-F6) | R6: =IF(H6="","",IFERROR(H6/C6,0)) | S6: =IF(I6="","",IFERROR(I6/D6,0)) | T6: =IF(J6="","",IFERROR(J6/E6,0)) | U6: =IF(K6="","",IFERROR(K6/F6,0))
B7: Apr | C7: 173.39151 | D7: 38.109745 | E7: 20.64194 | F7: =SUM(C7:E7) | H7: 36.94 | I7: 1.7 | J7: 115.3 | K7: =IF(H7="","",SUM(H7:J7)) | M7: =IF(H7="","",H7-C7) | N7: =IF(I7="","",I7-D7) | O7: =IF(J7="","",J7-E7) | P7: =IF(K7="","",K7-F7) | R7: =IF(H7="","",IFERROR(H7/C7,0)) | S7: =IF(I7="","",IFERROR(I7/D7,0)) | T7: =IF(J7="","",IFERROR(J7/E7,0)) | U7: =IF(K7="","",IFERROR(K7/F7,0))
B8: May | C8: 129.39052 | D8: 48.787473 | E8: 24.496506 | F8: =SUM(C8:E8) | H8: 135.53 | I8: 11.34 | J8: 106.34 | K8: =IF(H8="","",SUM(H8:J8)) | M8: =IF(H8="","",H8-C8) | N8: =IF(I8="","",I8-D8) | O8: =IF(J8="","",J8-E8) | P8: =IF(K8="","",K8-F8) | R8: =IF(H8="","",IFERROR(H8/C8,0)) | S8: =IF(I8="","",IFERROR(I8/D8,0)) | T8: =IF(J8="","",IFERROR(J8/E8,0)) | U8: =IF(K8="","",IFERROR(K8/F8,0))
B9: Jun | C9: 105.35994 | D9: 30.958343 | E9: 35.21842 | F9: =SUM(C9:E9) | H9: 110.45 | I9: 13.56 | J9: 75.43 | K9: =IF(H9="","",SUM(H9:J9)) | M9: =IF(H9="","",H9-C9) | N9: =IF(I9="","",I9-D9) | O9: =IF(J9="","",J9-E9) | P9: =IF(K9="","",K9-F9) | R9: =IF(H9="","",IFERROR(H9/C9,0)) | S9: =IF(I9="","",IFERROR(I9/D9,0)) | T9: =IF(J9="","",IFERROR(J9/E9,0)) | U9: =IF(K9="","",IFERROR(K9/F9,0))
B10: Jul | C10: 223.43512 | D10: 44.607798 | E10: 33.530264 | F10: =SUM(C10:E10) | H10: 98.37 | I10: 23.45 | J10: 67.77 | K10: =IF(H10="","",SUM(H10:J10)) | M10: =IF(H10="","",H10-C10) | N10: =IF(I10="","",I10-D10) | O10: =IF(J10="","",J10-E10) | P10: =IF(K10="","",K10-F10) | R10: =IF(H10="","",IFERROR(H10/C10,0)) | S10: =IF(I10="","",IFERROR(I10/D10,0)) | T10: =IF(J10="","",IFERROR(J10/E10,0)) | U10: =IF(K10="","",IFERROR(K10/F10,0))
B11: Aug | C11: 223.67888 | D11: 53.983255 | E11: 89.064216 | F11: =SUM(C11:E11) | H11: 210.45 | I11: 26.54 | J11: 123.65 | K11: =IF(H11="","",SUM(H11:J11)) | M11: =IF(H11="","",H11-C11) | N11: =IF(I11="","",I11-D11) | O11: =IF(J11="","",J11-E11) | P11: =IF(K11="","",K11-F11) | R11: =IF(H11="","",IFERROR(H11/C11,0)) | S11: =IF(I11="","",IFERROR(I11/D11,0)) | T11: =IF(J11="","",IFERROR(J11/E11,0)) | U11: =IF(K11="","",IFERROR(K11/F11,0))
B12: Sep | C12: 287.11122 | D12: 18.680757 | E12: 34.402698 | F12: =SUM(C12:E12) | H12: 253.56 | I12: 34.67 | J12: 89.56 | K12: =IF(H12="","",SUM(H12:J12)) | M12: =IF(H12="","",H12-C12) | N12: =IF(I12="","",I12-D12) | O12: =IF(J12="","",J12-E12) | P12: =IF(K12="","",K12-F12) | R12: =IF(H12="","",IFERROR(H12/C12,0)) | S12: =IF(I12="","",IFERROR(I12/D12,0)) | T12: =IF(J12="","",IFERROR(J12/E12,0)) | U12: =IF(K12="","",IFERROR(K12/F12,0))
B13: Oct | C13: 125.86418 | D13: 66.631194 | E13: 101.27959 | F13: =SUM(C13:E13) | H13: 280.38 | I13: 29.45 | J13: 167.78 | K13: =IF(H13="","",SUM(H13:J13)) | M13: =IF(H13="","",H13-C13) | N13: =IF(I13="","",I13-D13) | O13: =IF(J13="","",J13-E13) | P13: =IF(K13="","",K13-F13) | R13: =IF(H13="","",IFERROR(H13/C13,0)) | S13: =IF(I13="","",IFERROR(I13/D13,0)) | T13: =IF(J13="","",IFERROR(J13/E13,0)) | U13: =IF(K13="","",IFERROR(K13/F13,0))
B14: Nov | C14: 308.81908 | D14: 22.248009 | E14: 53.686859 | F14: =SUM(C14:E14) | H14: 395.98 | I14: 45.65 | J14: 198.89 | K14: =IF(H14="","",SUM(H14:J14)) | M14: =IF(H14="","",H14-C14) | N14: =IF(I14="","",I14-D14) | O14: =IF(J14="","",J14-E14) | P14: =IF(K14="","",K14-F14) | R14: =IF(H14="","",IFERROR(H14/C14,0)) | S14: =IF(I14="","",IFERROR(I14/D14,0)) | T14: =IF(J14="","",IFERROR(J14/E14,0)) | U14: =IF(K14="","",IFERROR(K14/F14,0))
B15: Dec | C15: 182.03953 | D15: 49.261252 | E15: 103.08376 | F15: =SUM(C15:E15) | H15: 114.34 | I15: 10.05 | J15: 78.43 | K15: =IF(H15="","",SUM(H15:J15)) | M15: =IF(H15="","",H15-C15) | N15: =IF(I15="","",I15-D15) | O15: =IF(J15="","",J15-E15) | P15: =IF(K15="","",K15-F15) | R15: =IF(H15="","",IFERROR(H15/C15,0)) | S15: =IF(I15="","",IFERROR(I15/D15,0)) | T15: =IF(J15="","",IFERROR(J15/E15,0)) | U15: =IF(K15="","",IFERROR(K15/F15,0))
C16: =SUM(C4:C15) | D16: =SUM(D4:D15) | E16: =SUM(E4:E15) | F16: =SUM(F4:F15) | H16: =SUM(H4:H15) | I16: =SUM(I4:I15) | J16: =SUM(J4:J15) | K16: =SUM(K4:K15) | M16: =SUM(M4:M15) | N16: =SUM(N4:N15) | O16: =SUM(O4:O15) | P16: =SUM(P4:P15) | R16: =IFERROR(H16/C16,0) | S16: =IFERROR(I16/D16,0) | T16: =IFERROR(J16/E16,0) | U16: =IFERROR(K16/F16,0)

Sheet Dashboard
A1: Budget vs Actual Dashboard(In Lacs)
B3: Month | C3: Budget | D3: Actual | E3: Variance | F3: In %
B4: JAN | C4: =IF(D4="","",Categorywise_Variance!F4) | D4: =IF(Categorywise_Variance!K4="","",Categorywise_Variance!K4) | E4: =IF(D4="","",D4-C4) | F4: =IFERROR(IF(D4="","",D4/C4),0)
B5: FEB | C5: =IF(D5="","",Categorywise_Variance!F5) | D5: =IF(Categorywise_Variance!K5="","",Categorywise_Variance!K5) | E5: =IF(D5="","",D5-C5) | F5: =IFERROR(IF(D5="","",D5/C5),0)
B6: MAR | C6: =IF(D6="","",Categorywise_Variance!F6) | D6: =IF(Categorywise_Variance!K6="","",Categorywise_Variance!K6) | E6: =IF(D6="","",D6-C6) | F6: =IFERROR(IF(D6="","",D6/C6),0)
B7: APR | C7: =IF(D7="","",Categorywise_Variance!F7) | D7: =IF(Categorywise_Variance!K7="","",Categorywise_Variance!K7) | E7: =IF(D7="","",D7-C7) | F7: =IFERROR(IF(D7="","",D7/C7),0)
B8: MAY | C8: =IF(D8="","",Categorywise_Variance!F8) | D8: =IF(Categorywise_Variance!K8="","",Categorywise_Variance!K8) | E8: =IF(D8="","",D8-C8) | F8: =IFERROR(IF(D8="","",D8/C8),0)
B9: JUN | C9: =IF(D9="","",Categorywise_Variance!F9) | D9: =IF(Categorywise_Variance!K9="","",Categorywise_Variance!K9) | E9: =IF(D9="","",D9-C9) | F9: =IFERROR(IF(D9="","",D9/C9),0)
B10: JUL | C10: =IF(D10="","",Categorywise_Variance!F10) | D10: =IF(Categorywise_Variance!K10="","",Categorywise_Variance!K10) | E10: =IF(D10="","",D10-C10) | F10: =IFERROR(IF(D10="","",D10/C10),0)
B11: AUG | C11: =IF(D11="","",Categorywise_Variance!F11) | D11: =IF(Categorywise_Variance!K11="","",Categorywise_Variance!K11) | E11: =IF(D11="","",D11-C11) | F11: =IFERROR(IF(D11="","",D11/C11),0)
B12: SEP | C12: =IF(D12="","",Categorywise_Variance!F12) | D12: =IF(Categorywise_Variance!K12="","",Categorywise_Variance!K12) | E12: =IF(D12="","",D12-C12) | F12: =IFERROR(IF(D12="","",D12/C12),0)
B13: OCT | C13: =IF(D13="","",Categorywise_Variance!F13) | D13: =IF(Categorywise_Variance!K13="","",Categorywise_Variance!K13) | E13: =IF(D13="","",D13-C13) | F13: =IFERROR(IF(D13="","",D13/C13),0)
B14: NOV | C14: =IF(D14="","",Categorywise_Variance!F14) | D14: =IF(Categorywise_Variance!K14="","",Categorywise_Variance!K14) | E14: =IF(D14="","",D14-C14) | F14: =IFERROR(IF(D14="","",D14/C14),0)
B15: DEC | C15: =IF(D15="","",Categorywise_Variance!F15) | D15: =IF(Categorywise_Variance!K15="","",Categorywise_Variance!K15) | E15: =IF(D15="","",D15-C15) | F15: =IFERROR(IF(D15="","",D15/C15),0)
B16: Total | C16: =SUM(C4:C15) | D16: =SUM(D4:D15) | E16: =SUM(E4:E15) | F16: =IFERROR(D16/C16,0)

Sheet YTM_Dashboard
A1: BudgetVSActual_YTM(In Lacs)
B3: Month | C3: Budget | D3: Actual | E3: Budget YTM | F3: Actual YTM | G3: Variance YTM | H3: % Achievement
B4: Jan | C4: =IF(Dashboard!C4="","",Dashboard!C4) | D4: =IF(Dashboard!D4="","",Dashboard!D4) | E4: =IF(C4="","",SUM(C$4:C4)) | F4: =IF(D4="","",SUM(D$4:D4)) | G4: =IF(F4&E4="","",F4-E4) | H4: =IFERROR(IF(G4="","",F4/E4),0)
B5: Feb | C5: =IF(Dashboard!C5="","",Dashboard!C5) | D5: =IF(Dashboard!D5="","",Dashboard!D5) | E5: =IF(C5="","",SUM(C$4:C5)) | F5: =IF(D5="","",SUM(D$4:D5)) | G5: =IF(F5&E5="","",F5-E5) | H5: =IFERROR(IF(G5="","",F5/E5),0)
B6: Mar | C6: =IF(Dashboard!C6="","",Dashboard!C6) | D6: =IF(Dashboard!D6="","",Dashboard!D6) | E6: =IF(C6="","",SUM(C$4:C6)) | F6: =IF(D6="","",SUM(D$4:D6)) | G6: =IF(F6&E6="","",F6-E6) | H6: =IFERROR(IF(G6="","",F6/E6),0)
B7: Apr | C7: =IF(Dashboard!C7="","",Dashboard!C7) | D7: =IF(Dashboard!D7="","",Dashboard!D7) | E7: =IF(C7="","",SUM(C$4:C7)) | F7: =IF(D7="","",SUM(D$4:D7)) | G7: =IF(F7&E7="","",F7-E7) | H7: =IFERROR(IF(G7="","",F7/E7),0)
B8: May | C8: =IF(Dashboard!C8="","",Dashboard!C8) | D8: =IF(Dashboard!D8="","",Dashboard!D8) | E8: =IF(C8="","",SUM(C$4:C8)) | F8: =IF(D8="","",SUM(D$4:D8)) | G8: =IF(F8&E8="","",F8-E8) | H8: =IFERROR(IF(G8="","",F8/E8),0)
B9: Jun | C9: =IF(Dashboard!C9="","",Dashboard!C9) | D9: =IF(Dashboard!D9="","",Dashboard!D9) | E9: =IF(C9="","",SUM(C$4:C9)) | F9: =IF(D9="","",SUM(D$4:D9)) | G9: =IF(F9&E9="","",F9-E9) | H9: =IFERROR(IF(G9="","",F9/E9),0)
B10: Jul | C10: =IF(Dashboard!C10="","",Dashboard!C10) | D10: =IF(Dashboard!D10="","",Dashboard!D10) | E10: =IF(C10="","",SUM(C$4:C10)) | F10: =IF(D10="","",SUM(D$4:D10)) | G10: =IF(F10&E10="","",F10-E10) | H10: =IFERROR(IF(G10="","",F10/E10),0)
B11: Aug | C11: =IF(Dashboard!C11="","",Dashboard!C11) | D11: =IF(Dashboard!D11="","",Dashboard!D11) | E11: =IF(C11="","",SUM(C$4:C11)) | F11: =IF(D11="","",SUM(D$4:D11)) | G11: =IF(F11&E11="","",F11-E11) | H11: =IFERROR(IF(G11="","",F11/E11),0)
B12: Sep | C12: =IF(Dashboard!C12="","",Dashboard!C12) | D12: =IF(Dashboard!D12="","",Dashboard!D12) | E12: =IF(C12="","",SUM(C$4:C12)) | F12: =IF(D12="","",SUM(D$4:D12)) | G12: =IF(F12&E12="","",F12-E12) | H12: =IFERROR(IF(G12="","",F12/E12),0)
B13: Oct | C13: =IF(Dashboard!C13="","",Dashboard!C13) | D13: =IF(Dashboard!D13="","",Dashboard!D13) | E13: =IF(C13="","",SUM(C$4:C13)) | F13: =IF(D13="","",SUM(D$4:D13)) | G13: =IF(F13&E13="","",F13-E13) | H13: =IFERROR(IF(G13="","",F13/E13),0)
B14: Nov | C14: =IF(Dashboard!C14="","",Dashboard!C14) | D14: =IF(Dashboard!D14="","",Dashboard!D14) | E14: =IF(C14="","",SUM(C$4:C14)) | F14: =IF(D14="","",SUM(D$4:D14)) | G14: =IF(F14&E14="","",F14-E14) | H14: =IFERROR(IF(G14="","",F14/E14),0)
B15: Dec | C15: =IF(Dashboard!C15="","",Dashboard!C15) | D15: =IF(Dashboard!D15="","",Dashboard!D15) | E15: =IF(C15="","",SUM(C$4:C15)) | F15: =IF(D15="","",SUM(D$4:D15)) | G15: =IF(F15&E15="","",F15-E15) | H15: =IFERROR(IF(G15="","",F15/E15),0)
B16: Total | C16: =SUM(C4:C15) | D16: =SUM(D4:D15)

Sheet Analysis
A1: Budget vs Actual Analysis
A3: Overall Performance
A5: Total Budget: | B5: =Categorywise_Variance!F16 | C5: Lacs
A6: Total Actual Sales: | B6: =Categorywise_Variance!K16 | C6: Lacs
A7: Overall Achievement: | B7: =Categorywise_Variance!U16 | C7: Lacs
A8: Overall Variance: | B8: =Categorywise_Variance!P16 | C8: Lacs
A10: Key Observations
A12: Sales remained below budget during January to April, resulting in a significant negative variance.
A13: Performance improved from May onwards, with actual sales exceeding the budget in May, June, September, October, and November.
A14: November recorded the highest positive variance (+255.77 Lacs) and 166% achievement.
A15: January showed the largest negative variance (-213.28 Lacs) with only 53% achievement.
A16: Despite strong performance in some months, the year closed at 96% of the annual budget.
A18: Category-wise Insights
A20: Export: Underperformed against budget in most months.
A21: B2B: Performance was inconsistent throughout the year.
A22: B2C: Consistently exceeded budget and was the strongest-performing sales channel.
A24: Conclusion
A25: The company achieved 96% of its annual sales budget. Early-year underperformance affected the overall result, while strong growth in the second half, particularly in October and November, significantly reduced the gap. Future focus should be on improving Export sales and maintaining the strong growth trend in the B2C segment.

Sheet QTY_SOLD_BudVSAct_OVERALL
B2: IN Lacs. | C2: Budgeted | J2: Actual | Q2: Variance | X2: Achivement %
B3: Row Labels | C3: Qty | D3: Gross Wt. | E3: Net Wt. | F3: Dia Wt. | G3: CLS Wt. | H3: Value | J3: Qty | K3: Gross Wt. | L3: Net Wt. | M3: Dia Wt. | N3: CLS Wt. | O3: Value | Q3: Qty | R3: Gross Wt. | S3: Net Wt. | T3: Dia Wt. | U3: CLS Wt. | V3: Value | X3: Qty | Y3: Gross Wt. | Z3: Net Wt. | AA3: Dia Wt. | AB3: CLS Wt. | AC3: Value
B4: Jan | C4: 27051.8 | D4: 28982.79 | E4: 25786.983 | F4: 261.5657 | G4: 12842.278 | H4: 46345743 | J4: 8770 | K4: 23381.681 | L4: 14248.359 | M4: 345.971 | N4: 29337.254 | O4: 23800045 | Q4: =J4-C4 | R4: =K4-D4 | S4: =L4-E4 | T4: =M4-F4 | U4: =N4-G4 | V4: =O4-H4 | X4: =IFERROR(J4/C4,0) | Y4: =IFERROR(K4/D4,0) | Z4: =IFERROR(L4/E4,0) | AA4: =IFERROR(M4/F4,0) | AB4: =IFERROR(N4/G4,0) | AC4: =IFERROR(O4/H4,0)
B5: Feb | C5: 19151.2 | D5: 13852.002 | E5: 12124.815 | F5: 215.5881 | G5: 16327.015 | H5: 24548471 | J5: 15342 | K5: 11271.049 | L5: 9866.062 | M5: 45.05 | N5: 8288.384 | O5: 11797586 | Q5: =J5-C5 | R5: =K5-D5 | S5: =L5-E5 | T5: =M5-F5 | U5: =N5-G5 | V5: =O5-H5 | X5: =IFERROR(J5/C5,0) | Y5: =IFERROR(K5/D5,0) | Z5: =IFERROR(L5/E5,0) | AA5: =IFERROR(M5/F5,0) | AB5: =IFERROR(N5/G5,0) | AC5: =IFERROR(O5/H5,0)
B6: Mar | C6: 8493.4 | D6: 22785.346 | E6: 19186.359 | F6: 152.6958 | G6: 12988.983 | H6: 30884193 | Q6: =J6-C6 | R6: =K6-D6 | S6: =L6-E6 | T6: =M6-F6 | U6: =N6-G6 | V6: =O6-H6 | X6: =IFERROR(J6/C6,0) | Y6: =IFERROR(K6/D6,0) | Z6: =IFERROR(L6/E6,0) | AA6: =IFERROR(M6/F6,0) | AB6: =IFERROR(N6/G6,0) | AC6: =IFERROR(O6/H6,0)
B7: Apr | C7: 5469.4 | D7: 11044.862 | E7: 9505.9407 | F7: 115.5662 | G7: 6421.913 | H7: 24322951 | Q7: =J7-C7 | R7: =K7-D7 | S7: =L7-E7 | T7: =M7-F7 | U7: =N7-G7 | V7: =O7-H7 | X7: =IFERROR(J7/C7,0) | Y7: =IFERROR(K7/D7,0) | Z7: =IFERROR(L7/E7,0) | AA7: =IFERROR(M7/F7,0) | AB7: =IFERROR(N7/G7,0) | AC7: =IFERROR(O7/H7,0)
B8: May | C8: 18744 | D8: 18701.298 | E8: 16169.632 | F8: 78.3629 | G8: 13306.067 | H8: 21363522 | Q8: =J8-C8 | R8: =K8-D8 | S8: =L8-E8 | T8: =M8-F8 | U8: =N8-G8 | V8: =O8-H8 | X8: =IFERROR(J8/C8,0) | Y8: =IFERROR(K8/D8,0) | Z8: =IFERROR(L8/E8,0) | AA8: =IFERROR(M8/F8,0) | AB8: =IFERROR(N8/G8,0) | AC8: =IFERROR(O8/H8,0)
B9: Jun | C9: 10936.3 | D9: 11773.933 | E9: 9852.2822 | F9: 165.6171 | G9: 10003.498 | H9: 20504861 | Q9: =J9-C9 | R9: =K9-D9 | S9: =L9-E9 | T9: =M9-F9 | U9: =N9-G9 | V9: =O9-H9 | X9: =IFERROR(J9/C9,0) | Y9: =IFERROR(K9/D9,0) | Z9: =IFERROR(L9/E9,0) | AA9: =IFERROR(M9/F9,0) | AB9: =IFERROR(N9/G9,0) | AC9: =IFERROR(O9/H9,0)
B10: Jul | C10: 18377.4 | D10: 24439.225 | E10: 20814.104 | F10: 261.0284 | G10: 17826.76 | H10: 33996363 | Q10: =J10-C10 | R10: =K10-D10 | S10: =L10-E10 | T10: =M10-F10 | U10: =N10-G10 | V10: =O10-H10 | X10: =IFERROR(J10/C10,0) | Y10: =IFERROR(K10/D10,0) | Z10: =IFERROR(L10/E10,0) | AA10: =IFERROR(M10/F10,0) | AB10: =IFERROR(N10/G10,0) | AC10: =IFERROR(O10/H10,0)
B11: Aug | C11: 10525 | D11: 17415.797 | E11: 13244.756 | F11: 165.0642 | G11: 19989.24 | H11: 37427525 | Q11: =J11-C11 | R11: =K11-D11 | S11: =L11-E11 | T11: =M11-F11 | U11: =N11-G11 | V11: =O11-H11 | X11: =IFERROR(J11/C11,0) | Y11: =IFERROR(K11/D11,0) | Z11: =IFERROR(L11/E11,0) | AA11: =IFERROR(M11/F11,0) | AB11: =IFERROR(N11/G11,0) | AC11: =IFERROR(O11/H11,0)
B12: Sep | C12: 11949.4 | D12: 25902.577 | E12: 21489.302 | F12: 202.1134 | G12: 20168.802 | H12: 34100574 | Q12: =J12-C12 | R12: =K12-D12 | S12: =L12-E12 | T12: =M12-F12 | U12: =N12-G12 | V12: =O12-H12 | X12: =IFERROR(J12/C12,0) | Y12: =IFERROR(K12/D12,0) | Z12: =IFERROR(L12/E12,0) | AA12: =IFERROR(M12/F12,0) | AB12: =IFERROR(N12/G12,0) | AC12: =IFERROR(O12/H12,0)
B13: Oct | C13: 6832.5 | D13: 31173.676 | E13: 14734.742 | F13: 214.3215 | G13: 7218.7267 | H13: 32403050 | Q13: =J13-C13 | R13: =K13-D13 | S13: =L13-E13 | T13: =M13-F13 | U13: =N13-G13 | V13: =O13-H13 | X13: =IFERROR(J13/C13,0) | Y13: =IFERROR(K13/D13,0) | Z13: =IFERROR(L13/E13,0) | AA13: =IFERROR(M13/F13,0) | AB13: =IFERROR(N13/G13,0) | AC13: =IFERROR(O13/H13,0)
B14: Nov | C14: 14373.9 | D14: 40539.455 | E14: 26996.206 | F14: 252.6097 | G14: 30374.399 | H14: 40152153 | Q14: =J14-C14 | R14: =K14-D14 | S14: =L14-E14 | T14: =M14-F14 | U14: =N14-G14 | V14: =O14-H14 | X14: =IFERROR(J14/C14,0) | Y14: =IFERROR(K14/D14,0) | Z14: =IFERROR(L14/E14,0) | AA14: =IFERROR(M14/F14,0) | AB14: =IFERROR(N14/G14,0) | AC14: =IFERROR(O14/H14,0)
B15: Dec | C15: 5111.9 | D15: 27180.853 | E15: 19585.742 | F15: 209.784 | G15: 36278.586 | H15: 33475218 | Q15: =J15-C15 | R15: =K15-D15 | S15: =L15-E15 | T15: =M15-F15 | U15: =N15-G15 | V15: =O15-H15 | X15: =IFERROR(J15/C15,0) | Y15: =IFERROR(K15/D15,0) | Z15: =IFERROR(L15/E15,0) | AA15: =IFERROR(M15/F15,0) | AB15: =IFERROR(N15/G15,0) | AC15: =IFERROR(O15/H15,0)
B16: Grand Total | C16: =SUM(C4:C15) | D16: =SUM(D4:D15) | E16: =SUM(E4:E15) | F16: =SUM(F4:F15) | G16: =SUM(G4:G15) | H16: =SUM(H4:H15) | J16: =SUM(J4:J15) | K16: =SUM(K4:K15) | L16: =SUM(L4:L15) | M16: =SUM(M4:M15) | N16: =SUM(N4:N15) | O16: =SUM(O4:O15) | Q16: =SUM(Q4:Q15) | R16: =SUM(R4:R15) | S16: =SUM(S4:S15) | T16: =SUM(T4:T15) | U16: =SUM(U4:U15) | V16: =SUM(V4:V15) | X16: =IFERROR(J16/C16,0) | Y16: =IFERROR(K16/D16,0) | Z16: =IFERROR(L16/E16,0) | AA16: =IFERROR(M16/F16,0) | AB16: =IFERROR(N16/G16,0) | AC16: =IFERROR(O16/H16,0)

Sheet QTY_SOLD_BudVSAct_Marketwise
A2: Total | B2: IN Lacs. | C2: Budgeted | J2: Actual | Q2: Variance | X2: Achivement %
B3: Row Labels | C3: Qty | D3: Gross Wt. | E3: Net Wt. | F3: Dia Wt. | G3: CLS Wt. | H3: Value | J3: Qty | K3: Gross Wt. | L3: Net Wt. | M3: Dia Wt. | N3: CLS Wt. | O3: Value | Q3: Qty | R3: Gross Wt. | S3: Net Wt. | T3: Dia Wt. | U3: CLS Wt. | V3: Value | X3: Qty | Y3: Gross Wt. | Z3: Net Wt. | AA3: Dia Wt. | AB3: CLS Wt. | AC3: Value
B4: Jan | C4: =C20+C36+C52 | D4: =D20+D36+D52 | E4: =E20+E36+E52 | F4: =F20+F36+F52 | G4: =G20+G36+G52 | H4: 35656715 | J4: =J20+J36+J52 | K4: =K20+K36+K52 | L4: =L20+L36+L52 | M4: =M20+M36+M52 | N4: =N20+N36+N52 | O4: 13445583 | Q4: =J4-C4 | R4: =K4-D4 | S4: =L4-E4 | T4: =M4-F4 | U4: =N4-G4 | V4: =O4-H4 | X4: =IFERROR(J4/C4,0) | Y4: =IFERROR(K4/D4,0) | Z4: =IFERROR(L4/E4,0) | AA4: =IFERROR(M4/F4,0) | AB4: =IFERROR(N4/G4,0) | AC4: =IFERROR(O4/H4,0)
B5: Feb | C5: =C21+C37+C53 | D5: =D21+D37+D53 | E5: =E21+E37+E53 | F5: =F21+F37+F53 | G5: =G21+G37+G53 | H5: 16100696 | J5: =J21+J37+J53 | K5: =K21+K37+K53 | L5: =L21+L37+L53 | M5: =M21+M37+M53 | N5: =N21+N37+N53 | O5: 4537902.7 | Q5: =J5-C5 | R5: =K5-D5 | S5: =L5-E5 | T5: =M5-F5 | U5: =N5-G5 | V5: =O5-H5 | X5: =IFERROR(J5/C5,0) | Y5: =IFERROR(K5/D5,0) | Z5: =IFERROR(L5/E5,0) | AA5: =IFERROR(M5/F5,0) | AB5: =IFERROR(N5/G5,0) | AC5: =IFERROR(O5/H5,0)
B6: Mar | C6: =C22+C38+C54 | D6: =D22+D38+D54 | E6: =E22+E38+E54 | F6: =F22+F38+F54 | G6: =G22+G38+G54 | H6: 20698984 | J6: =J22+J38+J54 | K6: =K22+K38+K54 | L6: =L22+L38+L54 | M6: =M22+M38+M54 | N6: =N22+N38+N54 | Q6: =J6-C6 | R6: =K6-D6 | S6: =L6-E6 | T6: =M6-F6 | U6: =N6-G6 | V6: =O6-H6 | X6: =IFERROR(J6/C6,0) | Y6: =IFERROR(K6/D6,0) | Z6: =IFERROR(L6/E6,0) | AA6: =IFERROR(M6/F6,0) | AB6: =IFERROR(N6/G6,0) | AC6: =IFERROR(O6/H6,0)
B7: Apr | C7: =C23+C39+C55 | D7: =D23+D39+D55 | E7: =E23+E39+E55 | F7: =F23+F39+F55 | G7: =G23+G39+G55 | H7: 17339151 | J7: =J23+J39+J55 | K7: =K23+K39+K55 | L7: =L23+L39+L55 | M7: =M23+M39+M55 | N7: =N23+N39+N55 | Q7: =J7-C7 | R7: =K7-D7 | S7: =L7-E7 | T7: =M7-F7 | U7: =N7-G7 | V7: =O7-H7 | X7: =IFERROR(J7/C7,0) | Y7: =IFERROR(K7/D7,0) | Z7: =IFERROR(L7/E7,0) | AA7: =IFERROR(M7/F7,0) | AB7: =IFERROR(N7/G7,0) | AC7: =IFERROR(O7/H7,0)
B8: May | C8: =C24+C40+C56 | D8: =D24+D40+D56 | E8: =E24+E40+E56 | F8: =F24+F40+F56 | G8: =G24+G40+G56 | H8: 12939052 | J8: =J24+J40+J56 | K8: =K24+K40+K56 | L8: =L24+L40+L56 | M8: =M24+M40+M56 | N8: =N24+N40+N56 | Q8: =J8-C8 | R8: =K8-D8 | S8: =L8-E8 | T8: =M8-F8 | U8: =N8-G8 | V8: =O8-H8 | X8: =IFERROR(J8/C8,0) | Y8: =IFERROR(K8/D8,0) | Z8: =IFERROR(L8/E8,0) | AA8: =IFERROR(M8/F8,0) | AB8: =IFERROR(N8/G8,0) | AC8: =IFERROR(O8/H8,0)
B9: Jun | C9: =C25+C41+C57 | D9: =D25+D41+D57 | E9: =E25+E41+E57 | F9: =F25+F41+F57 | G9: =G25+G41+G57 | H9: 10535994 | J9: =J25+J41+J57 | K9: =K25+K41+K57 | L9: =L25+L41+L57 | M9: =M25+M41+M57 | N9: =N25+N41+N57 | Q9: =J9-C9 | R9: =K9-D9 | S9: =L9-E9 | T9: =M9-F9 | U9: =N9-G9 | V9: =O9-H9 | X9: =IFERROR(J9/C9,0) | Y9: =IFERROR(K9/D9,0) | Z9: =IFERROR(L9/E9,0) | AA9: =IFERROR(M9/F9,0) | AB9: =IFERROR(N9/G9,0) | AC9: =IFERROR(O9/H9,0)
B10: Jul | C10: =C26+C42+C58 | D10: =D26+D42+D58 | E10: =E26+E42+E58 | F10: =F26+F42+F58 | G10: =G26+G42+G58 | H10: 22343512 | J10: =J26+J42+J58 | K10: =K26+K42+K58 | L10: =L26+L42+L58 | M10: =M26+M42+M58 | N10: =N26+N42+N58 | Q10: =J10-C10 | R10: =K10-D10 | S10: =L10-E10 | T10: =M10-F10 | U10: =N10-G10 | V10: =O10-H10 | X10: =IFERROR(J10/C10,0) | Y10: =IFERROR(K10/D10,0) | Z10: =IFERROR(L10/E10,0) | AA10: =IFERROR(M10/F10,0) | AB10: =IFERROR(N10/G10,0) | AC10: =IFERROR(O10/H10,0)
B11: Aug | C11: =C27+C43+C59 | D11: =D27+D43+D59 | E11: =E27+E43+E59 | F11: =F27+F43+F59 | G11: =G27+G43+G59 | H11: 22367888 | J11: =J27+J43+J59 | K11: =K27+K43+K59 | L11: =L27+L43+L59 | M11: =M27+M43+M59 | N11: =N27+N43+N59 | Q11: =J11-C11 | R11: =K11-D11 | S11: =L11-E11 | T11: =M11-F11 | U11: =N11-G11 | V11: =O11-H11 | X11: =IFERROR(J11/C11,0) | Y11: =IFERROR(K11/D11,0) | Z11: =IFERROR(L11/E11,0) | AA11: =IFERROR(M11/F11,0) | AB11: =IFERROR(N11/G11,0) | AC11: =IFERROR(O11/H11,0)
B12: Sep | C12: =C28+C44+C60 | D12: =D28+D44+D60 | E12: =E28+E44+E60 | F12: =F28+F44+F60 | G12: =G28+G44+G60 | H12: 28711122 | J12: =J28+J44+J60 | K12: =K28+K44+K60 | L12: =L28+L44+L60 | M12: =M28+M44+M60 | N12: =N28+N44+N60 | Q12: =J12-C12 | R12: =K12-D12 | S12: =L12-E12 | T12: =M12-F12 | U12: =N12-G12 | V12: =O12-H12 | X12: =IFERROR(J12/C12,0) | Y12: =IFERROR(K12/D12,0) | Z12: =IFERROR(L12/E12,0) | AA12: =IFERROR(M12/F12,0) | AB12: =IFERROR(N12/G12,0) | AC12: =IFERROR(O12/H12,0)
B13: Oct | C13: =C29+C45+C61 | D13: =D29+D45+D61 | E13: =E29+E45+E61 | F13: =F29+F45+F61 | G13: =G29+G45+G61 | H13: 12586418 | J13: =J29+J45+J61 | K13: =K29+K45+K61 | L13: =L29+L45+L61 | M13: =M29+M45+M61 | N13: =N29+N45+N61 | Q13: =J13-C13 | R13: =K13-D13 | S13: =L13-E13 | T13: =M13-F13 | U13: =N13-G13 | V13: =O13-H13 | X13: =IFERROR(J13/C13,0) | Y13: =IFERROR(K13/D13,0) | Z13: =IFERROR(L13/E13,0) | AA13: =IFERROR(M13/F13,0) | AB13: =IFERROR(N13/G13,0) | AC13: =IFERROR(O13/H13,0)
B14: Nov | C14: =C30+C46+C62 | D14: =D30+D46+D62 | E14: =E30+E46+E62 | F14: =F30+F46+F62 | G14: =G30+G46+G62 | H14: 30881908 | J14: =J30+J46+J62 | K14: =K30+K46+K62 | L14: =L30+L46+L62 | M14: =M30+M46+M62 | N14: =N30+N46+N62 | Q14: =J14-C14 | R14: =K14-D14 | S14: =L14-E14 | T14: =M14-F14 | U14: =N14-G14 | V14: =O14-H14 | X14: =IFERROR(J14/C14,0) | Y14: =IFERROR(K14/D14,0) | Z14: =IFERROR(L14/E14,0) | AA14: =IFERROR(M14/F14,0) | AB14: =IFERROR(N14/G14,0) | AC14: =IFERROR(O14/H14,0)
B15: Dec | C15: =C31+C47+C63 | D15: =D31+D47+D63 | E15: =E31+E47+E63 | F15: =F31+F47+F63 | G15: =G31+G47+G63 | H15: 18203953 | J15: =J31+J47+J63 | K15: =K31+K47+K63 | L15: =L31+L47+L63 | M15: =M31+M47+M63 | N15: =N31+N47+N63 | Q15: =J15-C15 | R15: =K15-D15 | S15: =L15-E15 | T15: =M15-F15 | U15: =N15-G15 | V15: =O15-H15 | X15: =IFERROR(J15/C15,0) | Y15: =IFERROR(K15/D15,0) | Z15: =IFERROR(L15/E15,0) | AA15: =IFERROR(M15/F15,0) | AB15: =IFERROR(N15/G15,0) | AC15: =IFERROR(O15/H15,0)
B16: Grand Total | C16: =SUM(C4:C15) | D16: =SUM(D4:D15) | E16: =SUM(E4:E15) | F16: =SUM(F4:F15) | G16: =SUM(G4:G15) | H16: =SUM(H4:H15) | J16: =SUM(J4:J15) | K16: =SUM(K4:K15) | L16: =SUM(L4:L15) | M16: =SUM(M4:M15) | N16: =SUM(N4:N15) | O16: =SUM(O4:O15) | Q16: =SUM(Q4:Q15) | R16: =SUM(R4:R15) | S16: =SUM(S4:S15) | T16: =SUM(T4:T15) | U16: =SUM(U4:U15) | V16: =SUM(V4:V15) | X16: =IFERROR(J16/C16,0) | Y16: =IFERROR(K16/D16,0) | Z16: =IFERROR(L16/E16,0) | AA16: =IFERROR(M16/F16,0) | AB16: =IFERROR(N16/G16,0) | AC16: =IFERROR(O16/H16,0)
A18: Export | B18: IN Lacs. | C18: Budgeted | J18: Actual | Q18: Variance | X18: Achivement %
B19: Row Labels | C19: Qty | D19: Gross Wt. | E19: Net Wt. | F19: Dia Wt. | G19: CLS Wt. | H19: Value | J19: Qty | K19: Gross Wt. | L19: Net Wt. | M19: Dia Wt. | N19: CLS Wt. | O19: Value | Q19: Qty | R19: Gross Wt. | S19: Net Wt. | T19: Dia Wt. | U19: CLS Wt. | V19: Value | X19: Qty | Y19: Gross Wt. | Z19: Net Wt. | AA19: Dia Wt. | AB19: CLS Wt. | AC19: Value
B20: Jan | C20: 14585 | D20: 24299.642 | E20: 21339.234 | F20: 170.9614 | G20: 11766.092 | H20: 35656715 | J20: 8042 | K20: 17451.893 | L20: 10963.11 | M20: 210.26 | N20: 25624.631 | O20: 13445583 | Q20: =J20-C20 | R20: =K20-D20 | S20: =L20-E20 | T20: =M20-F20 | U20: =N20-G20 | V20: =O20-H20 | X20: =IFERROR(J20/C20,0) | Y20: =IFERROR(K20/D20,0) | Z20: =IFERROR(L20/E20,0) | AA20: =IFERROR(M20/F20,0) | AB20: =IFERROR(N20/G20,0) | AC20: =IFERROR(O20/H20,0)
B21: Feb | C21: 5182.4 | D21: 12912.327 | E21: 11381.701 | F21: 122.7374 | G21: 12712.215 | H21: 16100696 | J21: 14941 | K21: 6934.041 | L21: 5937.59 | M21: 6.817 | N21: 5807.941 | O21: 4537902.7 | Q21: =J21-C21 | R21: =K21-D21 | S21: =L21-E21 | T21: =M21-F21 | U21: =N21-G21 | V21: =O21-H21 | X21: =IFERROR(J21/C21,0) | Y21: =IFERROR(K21/D21,0) | Z21: =IFERROR(L21/E21,0) | AA21: =IFERROR(M21/F21,0) | AB21: =IFERROR(N21/G21,0) | AC21: =IFERROR(O21/H21,0)
B22: Mar | C22: 7268.5 | D22: 16095.355 | E22: 13285.604 | F22: 110.5434 | G22: 9395.088 | H22: 20698984 | Q22: =J22-C22 | R22: =K22-D22 | S22: =L22-E22 | T22: =M22-F22 | U22: =N22-G22 | V22: =O22-H22 | X22: =IFERROR(J22/C22,0) | Y22: =IFERROR(K22/D22,0) | Z22: =IFERROR(L22/E22,0) | AA22: =IFERROR(M22/F22,0) | AB22: =IFERROR(N22/G22,0) | AC22: =IFERROR(O22/H22,0)
B23: Apr | C23: 4553.5 | D23: 8522.8822 | E23: 7279.9783 | F23: 92.8092 | G23: 5034.0979 | H23: 17339151 | Q23: =J23-C23 | R23: =K23-D23 | S23: =L23-E23 | T23: =M23-F23 | U23: =N23-G23 | V23: =O23-H23 | X23: =IFERROR(J23/C23,0) | Y23: =IFERROR(K23/D23,0) | Z23: =IFERROR(L23/E23,0) | AA23: =IFERROR(M23/F23,0) | AB23: =IFERROR(N23/G23,0) | AC23: =IFERROR(O23/H23,0)
B24: May | C24: 8185.2 | D24: 15604.644 | E24: 13460.67 | F24: 48.8947 | G24: 10208.977 | H24: 12939052 | Q24: =J24-C24 | R24: =K24-D24 | S24: =L24-E24 | T24: =M24-F24 | U24: =N24-G24 | V24: =O24-H24 | X24: =IFERROR(J24/C24,0) | Y24: =IFERROR(K24/D24,0) | Z24: =IFERROR(L24/E24,0) | AA24: =IFERROR(M24/F24,0) | AB24: =IFERROR(N24/G24,0) | AC24: =IFERROR(O24/H24,0)
B25: Jun | C25: 5779.1 | D25: 8490.6674 | E25: 7117.1004 | F25: 35.9706 | G25: 6678.2522 | H25: 10535994 | Q25: =J25-C25 | R25: =K25-D25 | S25: =L25-E25 | T25: =M25-F25 | U25: =N25-G25 | V25: =O25-H25 | X25: =IFERROR(J25/C25,0) | Y25: =IFERROR(K25/D25,0) | Z25: =IFERROR(L25/E25,0) | AA25: =IFERROR(M25/F25,0) | AB25: =IFERROR(N25/G25,0) | AC25: =IFERROR(O25/H25,0)
B26: Jul | C26: 15034.2 | D26: 20533.7 | E26: 17289.544 | F26: 54.0222 | G26: 15543.236 | H26: 22343512 | Q26: =J26-C26 | R26: =K26-D26 | S26: =L26-E26 | T26: =M26-F26 | U26: =N26-G26 | V26: =O26-H26 | X26: =IFERROR(J26/C26,0) | Y26: =IFERROR(K26/D26,0) | Z26: =IFERROR(L26/E26,0) | AA26: =IFERROR(M26/F26,0) | AB26: =IFERROR(N26/G26,0) | AC26: =IFERROR(O26/H26,0)
B27: Aug | C27: 9478.5 | D27: 16101.427 | E27: 12312.424 | F27: 60.8079 | G27: 17842.231 | H27: 22367888 | Q27: =J27-C27 | R27: =K27-D27 | S27: =L27-E27 | T27: =M27-F27 | U27: =N27-G27 | V27: =O27-H27 | X27: =IFERROR(J27/C27,0) | Y27: =IFERROR(K27/D27,0) | Z27: =IFERROR(L27/E27,0) | AA27: =IFERROR(M27/F27,0) | AB27: =IFERROR(N27/G27,0) | AC27: =IFERROR(O27/H27,0)
B28: Sep | C28: 11836.5 | D28: 25285.068 | E28: 21016.226 | F28: 182.7419 | G28: 19593.034 | H28: 28711122 | Q28: =J28-C28 | R28: =K28-D28 | S28: =L28-E28 | T28: =M28-F28 | U28: =N28-G28 | V28: =O28-H28 | X28: =IFERROR(J28/C28,0) | Y28: =IFERROR(K28/D28,0) | Z28: =IFERROR(L28/E28,0) | AA28: =IFERROR(M28/F28,0) | AB28: =IFERROR(N28/G28,0) | AC28: =IFERROR(O28/H28,0)
B29: Oct | C29: 5255.3 | D29: 12563.941 | E29: 11518.79 | F29: 42.8386 | G29: 4700.1273 | H29: 12586418 | Q29: =J29-C29 | R29: =K29-D29 | S29: =L29-E29 | T29: =M29-F29 | U29: =N29-G29 | V29: =O29-H29 | X29: =IFERROR(J29/C29,0) | Y29: =IFERROR(K29/D29,0) | Z29: =IFERROR(L29/E29,0) | AA29: =IFERROR(M29/F29,0) | AB29: =IFERROR(N29/G29,0) | AC29: =IFERROR(O29/H29,0)
B30: Nov | C30: 14072.9 | D30: 30961.938 | E30: 24511.203 | F30: 139.6807 | G30: 30064.376 | H30: 30881908 | Q30: =J30-C30 | R30: =K30-D30 | S30: =L30-E30 | T30: =M30-F30 | U30: =N30-G30 | V30: =O30-H30 | X30: =IFERROR(J30/C30,0) | Y30: =IFERROR(K30/D30,0) | Z30: =IFERROR(L30/E30,0) | AA30: =IFERROR(M30/F30,0) | AB30: =IFERROR(N30/G30,0) | AC30: =IFERROR(O30/H30,0)
B31: Dec | C31: 3971.9 | D31: 12737.802 | E31: 6693.2084 | F31: 123.5438 | G31: 29500.295 | H31: 18203953 | Q31: =J31-C31 | R31: =K31-D31 | S31: =L31-E31 | T31: =M31-F31 | U31: =N31-G31 | V31: =O31-H31 | X31: =IFERROR(J31/C31,0) | Y31: =IFERROR(K31/D31,0) | Z31: =IFERROR(L31/E31,0) | AA31: =IFERROR(M31/F31,0) | AB31: =IFERROR(N31/G31,0) | AC31: =IFERROR(O31/H31,0)
B32: Grand Total | C32: =SUM(C20:C31) | D32: =SUM(D20:D31) | E32: =SUM(E20:E31) | F32: =SUM(F20:F31) | G32: =SUM(G20:G31) | H32: =SUM(H20:H31) | J32: =SUM(J20:J31) | K32: =SUM(K20:K31) | L32: =SUM(L20:L31) | M32: =SUM(M20:M31) | N32: =SUM(N20:N31) | O32: =SUM(O20:O31) | Q32: =SUM(Q20:Q31) | R32: =SUM(R20:R31) | S32: =SUM(S20:S31) | T32: =SUM(T20:T31) | U32: =SUM(U20:U31) | V32: =SUM(V20:V31) | X32: =IFERROR(J32/C32,0) | Y32: =IFERROR(K32/D32,0) | Z32: =IFERROR(L32/E32,0) | AA32: =IFERROR(M32/F32,0) | AB32: =IFERROR(N32/G32,0) | AC32: =IFERROR(O32/H32,0)
A34: B2B | B34: IN Lacs. | C34: Budgeted | J34: Actual | Q34: Variance | X34: Achivement %
B35: Row Labels | C35: Qty | D35: Gross Wt. | E35: Net Wt. | F35: Dia Wt. | G35: CLS Wt. | H35: Value | J35: Qty | K35: Gross Wt. | L35: Net Wt. | M35: Dia Wt. | N35: CLS Wt. | O35: Value | Q35: Qty | R35: Gross Wt. | S35: Net Wt. | T35: Dia Wt. | U35: CLS Wt. | V35: Value | X35: Qty | Y35: Gross Wt. | Z35: Net Wt. | AA35: Dia Wt. | AB35: CLS Wt. | AC35: Value
B36: Jan | C36: 216.6 | D36: 3714.3342 | E36: 3596.1408 | F36: 10.9254 | G36: 556.6692 | H36: 3244924.6 | J36: 499 | K36: 2872.223 | L36: 2502.385 | M36: 2.235 | N36: 2675.733 | O36: 1588430.4 | Q36: =J36-C36 | R36: =K36-D36 | S36: =L36-E36 | T36: =M36-F36 | U36: =N36-G36 | V36: =O36-H36 | X36: =IFERROR(J36/C36,0) | Y36: =IFERROR(K36/D36,0) | Z36: =IFERROR(L36/E36,0) | AA36: =IFERROR(M36/F36,0) | AB36: =IFERROR(N36/G36,0) | AC36: =IFERROR(O36/H36,0)
B37: Feb | C37: 144.6 | D37: 646.9608 | E37: 486.2223 | F37: 29.3828 | G37: 767.3412 | H37: 3084628.5 | J37: 229 | K37: 3057.565 | L37: 782.864 | M37: 133.476 | N37: 1036.89 | O37: 8766031.4 | Q37: =J37-C37 | R37: =K37-D37 | S37: =L37-E37 | T37: =M37-F37 | U37: =N37-G37 | V37: =O37-H37 | X37: =IFERROR(J37/C37,0) | Y37: =IFERROR(K37/D37,0) | Z37: =IFERROR(L37/E37,0) | AA37: =IFERROR(M37/F37,0) | AB37: =IFERROR(N37/G37,0) | AC37: =IFERROR(O37/H37,0)
B38: Mar | C38: 938.2 | D38: 5350.7106 | E38: 4902.2439 | F38: 20.742 | G38: 2177.9796 | H38: 7158230.7 | Q38: =J38-C38 | R38: =K38-D38 | S38: =L38-E38 | T38: =M38-F38 | U38: =N38-G38 | V38: =O38-H38 | X38: =IFERROR(J38/C38,0) | Y38: =IFERROR(K38/D38,0) | Z38: =IFERROR(L38/E38,0) | AA38: =IFERROR(M38/F38,0) | AB38: =IFERROR(N38/G38,0) | AC38: =IFERROR(O38/H38,0)
B39: Apr | C39: 868.3 | D39: 2232.8362 | E39: 1950.5219 | F39: 9.3501 | G39: 1338.2561 | H39: 3810974.5 | Q39: =J39-C39 | R39: =K39-D39 | S39: =L39-E39 | T39: =M39-F39 | U39: =N39-G39 | V39: =O39-H39 | X39: =IFERROR(J39/C39,0) | Y39: =IFERROR(K39/D39,0) | Z39: =IFERROR(L39/E39,0) | AA39: =IFERROR(M39/F39,0) | AB39: =IFERROR(N39/G39,0) | AC39: =IFERROR(O39/H39,0)
B40: May | C40: 302.7 | D40: 1150.563 | E40: 981.3859 | F40: 21.8952 | G40: 185.6624 | H40: 4878747.3 | Q40: =J40-C40 | R40: =K40-D40 | S40: =L40-E40 | T40: =M40-F40 | U40: =N40-G40 | V40: =O40-H40 | X40: =IFERROR(J40/C40,0) | Y40: =IFERROR(K40/D40,0) | Z40: =IFERROR(L40/E40,0) | AA40: =IFERROR(M40/F40,0) | AB40: =IFERROR(N40/G40,0) | AC40: =IFERROR(O40/H40,0)
B41: Jun | C41: 1144.7 | D41: 2731.2586 | E41: 2270.355 | F41: 7.9894 | G41: 2158.6592 | H41: 3095834.3 | Q41: =J41-C41 | R41: =K41-D41 | S41: =L41-E41 | T41: =M41-F41 | U41: =N41-G41 | V41: =O41-H41 | X41: =IFERROR(J41/C41,0) | Y41: =IFERROR(K41/D41,0) | Z41: =IFERROR(L41/E41,0) | AA41: =IFERROR(M41/F41,0) | AB41: =IFERROR(N41/G41,0) | AC41: =IFERROR(O41/H41,0)
B42: Jul | C42: 302.3 | D42: 1891.3516 | E42: 1649.4477 | F42: 16.0287 | G42: 832.0039 | H42: 4460779.8 | Q42: =J42-C42 | R42: =K42-D42 | S42: =L42-E42 | T42: =M42-F42 | U42: =N42-G42 | V42: =O42-H42 | X42: =IFERROR(J42/C42,0) | Y42: =IFERROR(K42/D42,0) | Z42: =IFERROR(L42/E42,0) | AA42: =IFERROR(M42/F42,0) | AB42: =IFERROR(N42/G42,0) | AC42: =IFERROR(O42/H42,0)
B43: Aug | C43: 89.5 | D43: 563.1942 | E43: 354.734 | F43: 25.526 | G43: 799.4596 | H43: 5398325.5 | Q43: =J43-C43 | R43: =K43-D43 | S43: =L43-E43 | T43: =M43-F43 | U43: =N43-G43 | V43: =O43-H43 | X43: =IFERROR(J43/C43,0) | Y43: =IFERROR(K43/D43,0) | Z43: =IFERROR(L43/E43,0) | AA43: =IFERROR(M43/F43,0) | AB43: =IFERROR(N43/G43,0) | AC43: =IFERROR(O43/H43,0)
...
