Workbook

Sheet HistoricalFS
B2: ="Historical Financial Statement -"&'Data Sheet'!B1 -> Historical Financial Statement -TATA STEEL LTD
B3: years | C3: ='Data Sheet'!B16 -> 42825 | D3: ='Data Sheet'!C16 -> 43190 | E3: ='Data Sheet'!D16 -> 43555 | F3: ='Data Sheet'!E16 -> 43921 | G3: ='Data Sheet'!F16 -> 44286 | H3: ='Data Sheet'!G16 -> 44651 | I3: ='Data Sheet'!H16 -> 45016 | J3: ='Data Sheet'!I16 -> 45382 | ... L3: ='Data Sheet'!K16 -> 46112 | M3: LTM
A5: # | B5: Income Statements
B6: Sales | C6: =IFERROR('Data Sheet'!B17,0) -> 112299.42 | D6: =IFERROR('Data Sheet'!C17,0) -> 123249.07 | E6: =IFERROR('Data Sheet'!D17,0) -> 157668.99 | F6: =IFERROR('Data Sheet'!E17,0) -> 139816.65 | G6: =IFERROR('Data Sheet'!F17,0) -> 156477.4 | H6: =IFERROR('Data Sheet'!G17,0) -> 243959.17 | I6: =IFERROR('Data Sheet'!H17,0) -> 243352.69 | J6: =IFERROR('Data Sheet'!I17,0) -> 229170.78 | ... L6: =IFERROR('Data Sheet'!K17,0) -> 232139.94 | M6: =IFERROR(SUM('Data Sheet'!H42:K42),0) -> 239756.11
B7: Sales Growth | C7: - | D7: =D6/C6-1 -> 0.097504065 | E7: =E6/D6-1 -> 0.27927124 | F7: =F6/E6-1 -> -0.1132267 | G7: =G6/F6-1 -> 0.11916142 | H7: =H6/G6-1 -> 0.55906968 | I7: =I6/H6-1 -> -0.0024859898 | J7: =J6/I6-1 -> -0.058277186 | K7: =K6/J6-1 -> -0.046377073 | ... M7: =M6/L6-1 -> 0.032808529
B9: COGS | C9: =IFERROR(SUM('Data Sheet'!B18,'Data Sheet'!B20:B22)-1*'Data Sheet'!B19,0) -> 77577.09 | D9: =IFERROR(SUM('Data Sheet'!C18,'Data Sheet'!C20:C22)-1*'Data Sheet'!C19,0) -> 84710.05 | E9: =IFERROR(SUM('Data Sheet'!D18,'Data Sheet'!D20:D22)-1*'Data Sheet'!D19,0) -> 105590.05 | F9: =IFERROR(SUM('Data Sheet'!E18,'Data Sheet'!E20:E22)-1*'Data Sheet'!E19,0) -> 102560.94 | G9: =IFERROR(SUM('Data Sheet'!F18,'Data Sheet'!F20:F22)-1*'Data Sheet'!F19,0) -> 102979.74 | H9: =IFERROR(SUM('Data Sheet'!G18,'Data Sheet'!G20:G22)-1*'Data Sheet'!G19,0) -> 143605.19 | I9: =IFERROR(SUM('Data Sheet'!H18,'Data Sheet'!H20:H22)-1*'Data Sheet'!H19,0) -> 178329.36 | J9: =IFERROR(SUM('Data Sheet'!I18,'Data Sheet'!I20:I22)-1*'Data Sheet'!I19,0) -> 183154.84 | ... L9: =IFERROR(SUM('Data Sheet'!K18,'Data Sheet'!K20:K22)-1*'Data Sheet'!K19,0) -> 171435.78 | M9: =IFERROR(SUM('Data Sheet'!H43:K43),0) -> 203566.87
B10: COGS % Sales | C10: =C9/C6 -> 0.69080579 | D10: =D9/D6 -> 0.68730782 | E10: =E9/E6 -> 0.66969447 | F10: =F9/F6 -> 0.73353882 | G10: =G9/G6 -> 0.65811255 | H10: =H9/H6 -> 0.58864436 | I10: =I9/I6 -> 0.73280209 | J10: =J9/J6 -> 0.79920677 | ... M10: =M9/M6 -> 0.84905811
B12: Gross Profit | C12: =C9+C6 -> 189876.51 | D12: =D9+D6 -> 207959.12 | E12: =E9+E6 -> 263259.04 | F12: =F9+F6 -> 242377.59 | G12: =G9+G6 -> 259457.14 | H12: =H9+H6 -> 387564.36 | I12: =I9+I6 -> 421682.05 | J12: =J9+J6 -> 412325.62 | ... M12: =M9+M6 -> 443322.98
B13: Gross Margins | C13: =C12/C6 -> 1.6908058 | D13: =D12/D6 -> 1.6873078 | E13: =E12/E6 -> 1.6696945 | F13: =F12/F6 -> 1.7335388 | G13: =G12/G6 -> 1.6581125 | H13: =H12/H6 -> 1.5886444 | I13: =I12/I6 -> 1.7328021 | J13: =J12/J6 -> 1.7992068 | ... M13: =M12/M6 -> 1.8490581
B15: Selling & General Expenses | C15: =IFERROR(SUM('Data Sheet'!B23:B24),0) -> 21578.7 | D15: =IFERROR(SUM('Data Sheet'!C23:C24),0) -> 17105.83 | E15: =IFERROR(SUM('Data Sheet'!D23:D24),0) -> 22760.72 | F15: =IFERROR(SUM('Data Sheet'!E23:E24),0) -> 19792.65 | G15: =IFERROR(SUM('Data Sheet'!F23:F24),0) -> 22993.4 | H15: =IFERROR(SUM('Data Sheet'!G23:G24),0) -> 36864.03 | I15: =IFERROR(SUM('Data Sheet'!H23:H24),0) -> 32723.17 | J15: =IFERROR(SUM('Data Sheet'!I23:I24),0) -> 23768.02 | ... L15: =IFERROR(SUM('Data Sheet'!K23:K24),0) -> 26351.72
B16: S&G Exp % Sales | C16: =C15/C6 -> 0.19215326 | D16: =D15/D6 -> 0.13879074 | E16: =E15/E6 -> 0.14435762 | F16: =F15/F6 -> 0.14156147 | G16: =G15/G6 -> 0.1469439 | H16: =H15/H6 -> 0.15110738 | I16: =I15/I6 -> 0.13446808 | J16: =J15/J6 -> 0.10371313 | ... M16: =M15/M6 -> 0
B18: EBITDA | C18: =C12-C15 -> 168297.81 | D18: =D12-D15 -> 190853.29 | E18: =E12-E15 -> 240498.32 | F18: =F12-F15 -> 222584.94 | G18: =G12-G15 -> 236463.74 | H18: =H12-H15 -> 350700.33 | I18: =I12-I15 -> 388958.88 | J18: =J12-J15 -> 388557.6 | ... L18: =L12-L15 -> 377224 | M18: =IFERROR(SUM('Data Sheet'!H34:K34),0) -> 112689.12
B19: EBITDA Margins | C19: =C18/C6 -> 1.4986525 | D19: =D18/D6 -> 1.5485171 | E19: =E18/E6 -> 1.5253368 | F19: =F18/F6 -> 1.5919774 | G19: =G18/G6 -> 1.5111686 | H19: =H18/H6 -> 1.437537 | I19: =I18/I6 -> 1.598334 | J19: =J18/J6 -> 1.6954936 | ... M19: =M18/M6 -> 0.47001563
B21: Interest | C21: =IFERROR('Data Sheet'!B27,0) -> 5072.2 | D21: =IFERROR('Data Sheet'!C27,0) -> 5454.74 | E21: =IFERROR('Data Sheet'!D27,0) -> 7660.1 | F21: =IFERROR('Data Sheet'!E27,0) -> 7533.46 | G21: =IFERROR('Data Sheet'!F27,0) -> 7606.71 | H21: =IFERROR('Data Sheet'!G27,0) -> 5462.2 | I21: =IFERROR('Data Sheet'!H27,0) -> 6298.7 | J21: =IFERROR('Data Sheet'!I27,0) -> 7507.57 | ... L21: =IFERROR('Data Sheet'!K27,0) -> 7167.06 | M21: =IFERROR(SUM('Data Sheet'!H46:K46),0) -> 7085.14
B22: Interest % Sales | C22: =C21/C6 -> 0.045166752 | D22: =D21/D6 -> 0.044257859 | E22: =E21/E6 -> 0.048583428 | F22: =F21/F6 -> 0.053880993 | G22: =G21/G6 -> 0.048612196 | H22: =H21/H6 -> 0.022389812 | I22: =I21/I6 -> 0.02588301 | J22: =J21/J6 -> 0.032759717 | ... M22: =M21/M6 -> 0.029551447
B24: Depreciation | C24: =IFERROR('Data Sheet'!B26,0) -> 5672.88 | D24: =IFERROR('Data Sheet'!C26,0) -> 5741.7 | E24: =IFERROR('Data Sheet'!D26,0) -> 7341.83 | F24: =IFERROR('Data Sheet'!E26,0) -> 8440.73 | G24: =IFERROR('Data Sheet'!F26,0) -> 9233.64 | H24: =IFERROR('Data Sheet'!G26,0) -> 9100.87 | I24: =IFERROR('Data Sheet'!H26,0) -> 9335.2 | J24: =IFERROR('Data Sheet'!I26,0) -> 9882.16 | ... L24: =IFERROR('Data Sheet'!K26,0) -> 11954.51 | M24: =IFERROR(SUM('Data Sheet'!H45:K45),0) -> 12849.86
B25: Depreciation % Sales | C25: =C24/C6 -> 0.050515666 | D25: =D24/D6 -> 0.046586153 | E25: =E24/E6 -> 0.046564832 | F25: =F24/F6 -> 0.060369992 | G25: =G24/G6 -> 0.059009416 | H25: =H24/H6 -> 0.03730489 | I25: =I24/I6 -> 0.038360784 | J25: =J24/J6 -> 0.043121379 | ... M25: =M24/M6 -> 0.053595548
B27: Earnings Before Tax | C27: =IFERROR(C18-SUM(C24,C21),0) -> 157552.73 | D27: =IFERROR(D18-SUM(D24,D21),0) -> 179656.85 | E27: =IFERROR(E18-SUM(E24,E21),0) -> 225496.39 | F27: =IFERROR(F18-SUM(F24,F21),0) -> 206610.75 | G27: =IFERROR(G18-SUM(G24,G21),0) -> 219623.39 | H27: =IFERROR(H18-SUM(H24,H21),0) -> 336137.26 | I27: =IFERROR(I18-SUM(I24,I21),0) -> 373324.98 | J27: =IFERROR(J18-SUM(J24,J21),0) -> 371167.87 | ... M27: =IFERROR(M18-SUM(M24,M21),0) -> 92754.12
B28: EBT % Sales | C28: =C27/C6 -> 1.4029701 | D28: =D27/D6 -> 1.4576731 | E28: =E27/E6 -> 1.4301886 | F28: =F27/F6 -> 1.4777264 | G28: =G27/G6 -> 1.403547 | H28: =H27/H6 -> 1.3778423 | I28: =I27/I6 -> 1.5340902 | J28: =J27/J6 -> 1.6196125 | ... M28: =M27/M6 -> 0.38686864
B30: Tax | C30: =IFERROR('Data Sheet'!B29,0) -> 2778.01 | D30: =IFERROR('Data Sheet'!C29,0) -> 3392.33 | E30: =IFERROR('Data Sheet'!D29,0) -> 6718.43 | F30: =IFERROR('Data Sheet'!E29,0) -> -2568.41 | G30: =IFERROR('Data Sheet'!F29,0) -> 5653.9 | H30: =IFERROR('Data Sheet'!G29,0) -> 8477.55 | I30: =IFERROR('Data Sheet'!H29,0) -> 10159.77 | J30: =IFERROR('Data Sheet'!I29,0) -> 3762.57 | ... L30: =IFERROR('Data Sheet'!K29,0) -> 5082.87 | M30: =IFERROR(SUM('Data Sheet'!H48:K48),0) -> 5475.44
B31: Effective Tax Rate | C31: =C30/C27 -> 0.017632256 | D31: =D30/D27 -> 0.018882275 | E31: =E30/E27 -> 0.029793958 | F31: =F30/F27 -> -0.012431154 | G31: =G30/G27 -> 0.025743615 | H31: =H30/H27 -> 0.025220501 | I31: =I30/I27 -> 0.027214279 | J31: =J30/J27 -> 0.010137111 | ... M31: =M30/M27 -> 0.059031771
B33: Net Profit | C33: =IFERROR(C27-C30,0) -> 154774.72 | D33: =IFERROR(D27-D30,0) -> 176264.52 | E33: =IFERROR(E27-E30,0) -> 218777.96 | F33: =IFERROR(F27-F30,0) -> 209179.16 | G33: =IFERROR(G27-G30,0) -> 213969.49 | H33: =IFERROR(H27-H30,0) -> 327659.71 | I33: =IFERROR(I27-I30,0) -> 363165.21 | J33: =IFERROR(J27-J30,0) -> 367405.3 | ... M33: =IFERROR(M27-M30,0) -> 87278.68
B34: Net Margins | C34: =C33/C6 -> 1.3782326 | D34: =D33/D6 -> 1.4301489 | E34: =E33/E6 -> 1.3875776 | F34: =F33/F6 -> 1.4960962 | G34: =G33/G6 -> 1.3674147 | H34: =H33/H6 -> 1.3430924 | I34: =I33/I6 -> 1.4923411 | J34: =J33/J6 -> 1.6031944 | ... M34: =M33/M6 -> 0.3640311
B36: No of Equity Shares | C36: =IFERROR('Data Sheet'!B93,0) -> 1126.62 | D36: =IFERROR('Data Sheet'!C93,0) -> 1126.48 | E36: =IFERROR('Data Sheet'!D93,0) -> 1126.49 | F36: =IFERROR('Data Sheet'!E93,0) -> 1126.49 | G36: =IFERROR('Data Sheet'!F93,0) -> 1196.59 | H36: =IFERROR('Data Sheet'!G93,0) -> 1221.3 | I36: =IFERROR('Data Sheet'!H93,0) -> 1222.15 | J36: =IFERROR('Data Sheet'!I93,0) -> 1248.35 | ... M36: =IFERROR('Data Sheet'!L93,0) -> 0
B38: EPS | C38: =IFERROR(C33/C36,0) -> 137.3797 | D38: =IFERROR(D33/D36,0) -> 156.47372 | E38: =IFERROR(E33/E36,0) -> 194.21207 | F38: =IFERROR(F33/F36,0) -> 185.69109 | G38: =IFERROR(G33/G36,0) -> 178.81604 | H38: =IFERROR(H33/H36,0) -> 268.28765 | I38: =IFERROR(I33/I36,0) -> 297.15273 | J38: =IFERROR(J33/J36,0) -> 294.31273 | ... M38: =IFERROR(M33/M36,0) -> 0
B39: EPS Growth % | D39: =IFERROR(D38/C38-1,0) -> 0.13898721 | E39: =IFERROR(E38/D38-1,0) -> 0.24118012 | F39: =IFERROR(F38/E38-1,0) -> -0.043874621 | G39: =IFERROR(G38/F38-1,0) -> -0.037024122 | H39: =IFERROR(H38/G38-1,0) -> 0.5003556 | I39: =IFERROR(I38/H38-1,0) -> 0.10759004 | J39: =IFERROR(J38/I38-1,0) -> -0.0095573681 | K39: =IFERROR(K38/J38-1,0) -> -0.059003613 | ... M39: =IFERROR(M38/L38-1,0) -> -1
B41: Dividend per share | C41: =IFERROR('Data Sheet'!B31/HistoricalFS!C36,0) -> 0.86119543 | D41: =IFERROR('Data Sheet'!C31/HistoricalFS!D36,0) -> 1.0163962 | E41: =IFERROR('Data Sheet'!D31/HistoricalFS!E36,0) -> 1.32129 | F41: =IFERROR('Data Sheet'!E31/HistoricalFS!F36,0) -> 1.0163872 | G41: =IFERROR('Data Sheet'!F31/HistoricalFS!G36,0) -> 2.5021269 | H41: =IFERROR('Data Sheet'!G31/HistoricalFS!H36,0) -> 5.0996234 | I41: =IFERROR('Data Sheet'!H31/HistoricalFS!I36,0) -> 3.5973162 | J41: =IFERROR('Data Sheet'!I31/HistoricalFS!J36,0) -> 3.5973725 | ... M41: =IFERROR('Data Sheet'!L31/HistoricalFS!M36,0) -> 0
B42: Dividend Payout Ratio | C42: =IFERROR(C41/C38,0) -> 0.006268724 | D42: =IFERROR(D41/D38,0) -> 0.0064956351 | E42: =IFERROR(E41/E38,0) -> 0.0068033361 | F42: =IFERROR(F41/F38,0) -> 0.0054735376 | G42: =IFERROR(G41/G38,0) -> 0.013992743 | H42: =IFERROR(H41/H38,0) -> 0.019008043 | I42: =IFERROR(I41/I38,0) -> 0.01210595 | J42: =IFERROR(J41/J38,0) -> 0.012222959 | ... M42: =IFERROR(M41/M38,0) -> 0
B44: RetainedEarnings | C44: =IFERROR(1-C42,0) -> 0.99373128 | D44: =IFERROR(1-D42,0) -> 0.99350436 | E44: =IFERROR(1-E42,0) -> 0.99319666 | F44: =IFERROR(1-F42,0) -> 0.99452646 | G44: =IFERROR(1-G42,0) -> 0.98600726 | H44: =IFERROR(1-H42,0) -> 0.98099196 | I44: =IFERROR(1-I42,0) -> 0.98789405 | J44: =IFERROR(1-J42,0) -> 0.98777704 | ... M44: =IFERROR(1-M42,0) -> 1
A46: # | B46: Balance Sheet
B48: Equity Share Capital | C48: =IFERROR('Data Sheet'!B57,0) -> 970.24 | D48: =IFERROR('Data Sheet'!C57,0) -> 1144.95 | E48: =IFERROR('Data Sheet'!D57,0) -> 1144.94 | F48: =IFERROR('Data Sheet'!E57,0) -> 1144.95 | G48: =IFERROR('Data Sheet'!F57,0) -> 1197.61 | H48: =IFERROR('Data Sheet'!G57,0) -> 1221.21 | I48: =IFERROR('Data Sheet'!H57,0) -> 1221.24 | J48: =IFERROR('Data Sheet'!I57,0) -> 1247.44 | ... L48: =IFERROR('Data Sheet'!K57,0) -> 1247.44
B49: Reserves | C49: =IFERROR('Data Sheet'!B58,0) -> 36849.08 | D49: =IFERROR('Data Sheet'!C58,0) -> 59725.67 | E49: =IFERROR('Data Sheet'!D58,0) -> 67780.14 | F49: =IFERROR('Data Sheet'!E58,0) -> 72431.35 | G49: =IFERROR('Data Sheet'!F58,0) -> 73041.16 | H49: =IFERROR('Data Sheet'!G58,0) -> 113221.83 | I49: =IFERROR('Data Sheet'!H58,0) -> 101860.86 | J49: =IFERROR('Data Sheet'!I58,0) -> 90788.32 | ... L49: =IFERROR('Data Sheet'!K58,0) -> 100920.21
B50: Borrowings | C50: =IFERROR('Data Sheet'!B59,0) -> 83014.49 | D50: =IFERROR('Data Sheet'!C59,0) -> 92147.05 | E50: =IFERROR('Data Sheet'!D59,0) -> 100816.22 | F50: =IFERROR('Data Sheet'!E59,0) -> 116328.2 | G50: =IFERROR('Data Sheet'!F59,0) -> 88501.41 | H50: =IFERROR('Data Sheet'!G59,0) -> 75561.35 | I50: =IFERROR('Data Sheet'!H59,0) -> 84893.05 | J50: =IFERROR('Data Sheet'!I59,0) -> 87082.12 | ... L50: =IFERROR('Data Sheet'!K59,0) -> 92381.68
B51: Other Liabilities | C51: =IFERROR('Data Sheet'!B60,0) -> 51613.56 | D51: =IFERROR('Data Sheet'!C60,0) -> 55704.47 | E51: =IFERROR('Data Sheet'!D60,0) -> 63032.14 | F51: =IFERROR('Data Sheet'!E60,0) -> 59244.62 | G51: =IFERROR('Data Sheet'!F60,0) -> 81169.01 | H51: =IFERROR('Data Sheet'!G60,0) -> 92417.28 | I51: =IFERROR('Data Sheet'!H60,0) -> 97420.63 | J51: =IFERROR('Data Sheet'!I60,0) -> 90194.54 | ... L51: =IFERROR('Data Sheet'!K60,0) -> 101965.29
B52: Total Liabilites | C52: =IFERROR('Data Sheet'!B61,0) -> 172447.37 | D52: =IFERROR('Data Sheet'!C61,0) -> 208722.14 | E52: =IFERROR('Data Sheet'!D61,0) -> 232773.44 | F52: =IFERROR('Data Sheet'!E61,0) -> 249149.12 | G52: =IFERROR('Data Sheet'!F61,0) -> 243909.19 | H52: =IFERROR('Data Sheet'!G61,0) -> 282421.67 | I52: =IFERROR('Data Sheet'!H61,0) -> 285395.78 | J52: =IFERROR('Data Sheet'!I61,0) -> 269312.42 | ... L52: =IFERROR('Data Sheet'!K61,0) -> 296514.62
B54: Fixed Assest Net Block | C54: =IFERROR('Data Sheet'!B62,0) -> 92006.55 | D54: =IFERROR('Data Sheet'!C62,0) -> 96104.89 | E54: =IFERROR('Data Sheet'!D62,0) -> 124441.91 | F54: =IFERROR('Data Sheet'!E62,0) -> 134550.66 | G54: =IFERROR('Data Sheet'!F62,0) -> 135775.18 | H54: =IFERROR('Data Sheet'!G62,0) -> 133287.83 | I54: =IFERROR('Data Sheet'!H62,0) -> 146621.46 | J54: =IFERROR('Data Sheet'!I62,0) -> 148814.38 | ... L54: =IFERROR('Data Sheet'!K62,0) -> 179908.13
B55: Capital Work in Progress | C55: =IFERROR('Data Sheet'!B63,0) -> 15784.13 | D55: =IFERROR('Data Sheet'!C63,0) -> 16614.41 | E55: =IFERROR('Data Sheet'!D63,0) -> 18641.21 | F55: =IFERROR('Data Sheet'!E63,0) -> 19496.83 | G55: =IFERROR('Data Sheet'!F63,0) -> 19007.4 | H55: =IFERROR('Data Sheet'!G63,0) -> 22045.55 | I55: =IFERROR('Data Sheet'!H63,0) -> 31213.02 | J55: =IFERROR('Data Sheet'!I63,0) -> 34355.53 | ... L55: =IFERROR('Data Sheet'!K63,0) -> 28496.71
B56: Investments | C56: =IFERROR('Data Sheet'!B64,0) -> 12457.12 | D56: =IFERROR('Data Sheet'!C64,0) -> 17899.47 | E56: =IFERROR('Data Sheet'!D64,0) -> 5738.17 | F56: =IFERROR('Data Sheet'!E64,0) -> 6285.18 | G56: =IFERROR('Data Sheet'!F64,0) -> 10681.93 | H56: =IFERROR('Data Sheet'!G64,0) -> 13139.85 | I56: =IFERROR('Data Sheet'!H64,0) -> 8410.31 | J56: =IFERROR('Data Sheet'!I64,0) -> 6257.57 | ... L56: =IFERROR('Data Sheet'!K64,0) -> 7088.85
B57: Other Assets | C57: =IFERROR('Data Sheet'!B65-SUM('Data Sheet'!B67:B69),0) -> 10887.88 | D57: =IFERROR('Data Sheet'!C65-SUM('Data Sheet'!C67:C69),0) -> 29418.96 | E57: =IFERROR('Data Sheet'!D65-SUM('Data Sheet'!D67:D69),0) -> 37143.68 | F57: =IFERROR('Data Sheet'!E65-SUM('Data Sheet'!E67:E69),0) -> 41808.1 | G57: =IFERROR('Data Sheet'!F65-SUM('Data Sheet'!F67:F69),0) -> 29846.28 | H57: =IFERROR('Data Sheet'!G65-SUM('Data Sheet'!G67:G69),0) -> 36978.69 | I57: =IFERROR('Data Sheet'!H65-SUM('Data Sheet'!H67:H69),0) -> 23121.16 | J57: =IFERROR('Data Sheet'!I65-SUM('Data Sheet'!I67:I69),0) -> 15786.18 | ... L57: =IFERROR('Data Sheet'!K65-SUM('Data Sheet'!K67:K69),0) -> 18797.29
B58: Total Non-current Asset | C58: =IFERROR(SUM(C54:C57),0) -> 131135.68 | D58: =IFERROR(SUM(D54:D57),0) -> 160037.73 | E58: =IFERROR(SUM(E54:E57),0) -> 185964.97 | F58: =IFERROR(SUM(F54:F57),0) -> 202140.77 | G58: =IFERROR(SUM(G54:G57),0) -> 195310.79 | H58: =IFERROR(SUM(H54:H57),0) -> 205451.92 | I58: =IFERROR(SUM(I54:I57),0) -> 209365.95 | J58: =IFERROR(SUM(J54:J57),0) -> 205213.66 | ... L58: =IFERROR(SUM(L54:L57),0) -> 234290.98
...

Sheet Ratio Analysis
B2: ="Ratio Analysis -"&'Data Sheet'!B1 -> Ratio Analysis -TATA STEEL LTD
B3: years | C3: ='Data Sheet'!B16 -> 42825 | D3: ='Data Sheet'!C16 -> 43190 | E3: ='Data Sheet'!D16 -> 43555 | F3: ='Data Sheet'!E16 -> 43921 | G3: ='Data Sheet'!F16 -> 44286 | H3: ='Data Sheet'!G16 -> 44651 | I3: ='Data Sheet'!H16 -> 45016 | J3: ='Data Sheet'!I16 -> 45382 | ... L3: ='Data Sheet'!K16 -> 46112 | M3: Trend | N3: Mean | O3: Median
B5: SalesGrowth | D5: =IFERROR(HistoricalFS!D7,0) -> 0.097504065 | E5: =IFERROR(HistoricalFS!E7,0) -> 0.27927124 | F5: =IFERROR(HistoricalFS!F7,0) -> -0.1132267 | G5: =IFERROR(HistoricalFS!G7,0) -> 0.11916142 | H5: =IFERROR(HistoricalFS!H7,0) -> 0.55906968 | I5: =IFERROR(HistoricalFS!I7,0) -> -0.0024859898 | J5: =IFERROR(HistoricalFS!J7,0) -> -0.058277186 | K5: =IFERROR(HistoricalFS!K7,0) -> -0.046377073 | L5: =IFERROR(HistoricalFS!L7,0) -> 0.062218696 | N5: =IFERROR(AVERAGE(D5:L5),0) -> 0.099650904 | O5: =IFERROR(MEDIAN(C5:L5),0) -> 0.062218696
B6: EBITDA Growth | D6: =IFERROR(HistoricalFS!D18/HistoricalFS!C18-1,0) -> 0.13402123 | E6: =IFERROR(HistoricalFS!E18/HistoricalFS!D18-1,0) -> 0.26012143 | F6: =IFERROR(HistoricalFS!F18/HistoricalFS!E18-1,0) -> -0.074484429 | G6: =IFERROR(HistoricalFS!G18/HistoricalFS!F18-1,0) -> 0.062352826 | H6: =IFERROR(HistoricalFS!H18/HistoricalFS!G18-1,0) -> 0.48310405 | I6: =IFERROR(HistoricalFS!I18/HistoricalFS!H18-1,0) -> 0.10909186 | J6: =IFERROR(HistoricalFS!J18/HistoricalFS!I18-1,0) -> -0.0010316772 | K6: =IFERROR(HistoricalFS!K18/HistoricalFS!J18-1,0) -> -0.051032768 | L6: =IFERROR(HistoricalFS!L18/HistoricalFS!K18-1,0) -> 0.023040182 | N6: =IFERROR(AVERAGE(D6:L6),0) -> 0.1050203 | O6: =IFERROR(MEDIAN(C6:L6),0) -> 0.062352826
B7: EBIT Growth | D7: =IFERROR(HistoricalFS!D27/HistoricalFS!C27-1,0) -> 0.14029665 | E7: =IFERROR(HistoricalFS!E27/HistoricalFS!D27-1,0) -> 0.25515053 | F7: =IFERROR(HistoricalFS!F27/HistoricalFS!E27-1,0) -> -0.083751407 | G7: =IFERROR(HistoricalFS!G27/HistoricalFS!F27-1,0) -> 0.062981428 | H7: =IFERROR(HistoricalFS!H27/HistoricalFS!G27-1,0) -> 0.53051667 | I7: =IFERROR(HistoricalFS!I27/HistoricalFS!H27-1,0) -> 0.11063254 | J7: =IFERROR(HistoricalFS!J27/HistoricalFS!I27-1,0) -> -0.0057781025 | K7: =IFERROR(HistoricalFS!K27/HistoricalFS!J27-1,0) -> -0.054427448 | L7: =IFERROR(HistoricalFS!L27/HistoricalFS!K27-1,0) -> 0.020333243 | N7: =IFERROR(AVERAGE(D7:L7),0) -> 0.10843934 | O7: =IFERROR(MEDIAN(C7:L7),0) -> 0.062981428
B8: Net Profit Growth | D8: =IFERROR(HistoricalFS!D33/HistoricalFS!C33-1,0) -> 0.13884567 | E8: =IFERROR(HistoricalFS!E33/HistoricalFS!D33-1,0) -> 0.24119114 | F8: =IFERROR(HistoricalFS!F33/HistoricalFS!E33-1,0) -> -0.043874621 | G8: =IFERROR(HistoricalFS!G33/HistoricalFS!F33-1,0) -> 0.022900608 | H8: =IFERROR(HistoricalFS!H33/HistoricalFS!G33-1,0) -> 0.53133846 | I8: =IFERROR(HistoricalFS!I33/HistoricalFS!H33-1,0) -> 0.1083609 | J8: =IFERROR(HistoricalFS!J33/HistoricalFS!I33-1,0) -> 0.011675375 | K8: =IFERROR(HistoricalFS!K33/HistoricalFS!J33-1,0) -> -0.059003613 | L8: =IFERROR(HistoricalFS!L33/HistoricalFS!K33-1,0) -> 0.021093229 | N8: =IFERROR(AVERAGE(D8:L8),0) -> 0.10805857 | O8: =IFERROR(MEDIAN(C8:L8),0) -> 0.022900608
B9: Dividend Growth | D9: =IFERROR(HistoricalFS!D41/HistoricalFS!C41-1,0) -> 0.18021551 | E9: =IFERROR(HistoricalFS!E41/HistoricalFS!D41-1,0) -> 0.29997536 | F9: =IFERROR(HistoricalFS!F41/HistoricalFS!E41-1,0) -> -0.23076148 | G9: =IFERROR(HistoricalFS!G41/HistoricalFS!F41-1,0) -> 1.4617851 | H9: =IFERROR(HistoricalFS!H41/HistoricalFS!G41-1,0) -> 1.0381154 | I9: =IFERROR(HistoricalFS!I41/HistoricalFS!H41-1,0) -> -0.29459179 | J9: =IFERROR(HistoricalFS!J41/HistoricalFS!I41-1,0) -> 1.5657977e-05 | K9: =IFERROR(HistoricalFS!K41/HistoricalFS!J41-1,0) -> 0 | L9: =IFERROR(HistoricalFS!L41/HistoricalFS!K41-1,0) -> 0.1111121 | N9: =IFERROR(AVERAGE(D9:L9),0) -> 0.28509621 | O9: =IFERROR(MEDIAN(C9:L9),0) -> 0.1111121
B11: Gross Margin | C11: =IFERROR(HistoricalFS!C13,0) -> 1.6908058 | D11: =IFERROR(HistoricalFS!D13,0) -> 1.6873078 | E11: =IFERROR(HistoricalFS!E13,0) -> 1.6696945 | F11: =IFERROR(HistoricalFS!F13,0) -> 1.7335388 | G11: =IFERROR(HistoricalFS!G13,0) -> 1.6581125 | H11: =IFERROR(HistoricalFS!H13,0) -> 1.5886444 | I11: =IFERROR(HistoricalFS!I13,0) -> 1.7328021 | J11: =IFERROR(HistoricalFS!J13,0) -> 1.7992068 | ... L11: =IFERROR(HistoricalFS!L13,0) -> 1.7385019 | N11: =IFERROR(AVERAGE(C11:L11),0) -> 1.7084343 | O11: =IFERROR(MEDIAN(C11:L11),0) -> 1.7118039
B12: EBITDA Margin | C12: =IFERROR(HistoricalFS!C19,0) -> 1.4986525 | D12: =IFERROR(HistoricalFS!D19,0) -> 1.5485171 | E12: =IFERROR(HistoricalFS!E19,0) -> 1.5253368 | F12: =IFERROR(HistoricalFS!F19,0) -> 1.5919774 | G12: =IFERROR(HistoricalFS!G19,0) -> 1.5111686 | H12: =IFERROR(HistoricalFS!H19,0) -> 1.437537 | I12: =IFERROR(HistoricalFS!I19,0) -> 1.598334 | J12: =IFERROR(HistoricalFS!J19,0) -> 1.6954936 | ... L12: =IFERROR(HistoricalFS!L19,0) -> 1.6249853 | N12: =IFERROR(AVERAGE(C12:L12),0) -> 1.5719218 | O12: =IFERROR(MEDIAN(C12:L12),0) -> 1.5702472
B13: EBIT Margin | C13: =IFERROR((HistoricalFS!C18-HistoricalFS!C24)/HistoricalFS!C6,0) -> 1.4481369 | D13: =IFERROR((HistoricalFS!D18-HistoricalFS!D24)/HistoricalFS!D6,0) -> 1.5019309 | E13: =IFERROR((HistoricalFS!E18-HistoricalFS!E24)/HistoricalFS!E6,0) -> 1.478772 | F13: =IFERROR((HistoricalFS!F18-HistoricalFS!F24)/HistoricalFS!F6,0) -> 1.5316074 | G13: =IFERROR((HistoricalFS!G18-HistoricalFS!G24)/HistoricalFS!G6,0) -> 1.4521592 | H13: =IFERROR((HistoricalFS!H18-HistoricalFS!H24)/HistoricalFS!H6,0) -> 1.4002321 | I13: =IFERROR((HistoricalFS!I18-HistoricalFS!I24)/HistoricalFS!I6,0) -> 1.5599732 | J13: =IFERROR((HistoricalFS!J18-HistoricalFS!J24)/HistoricalFS!J6,0) -> 1.6523723 | ... L13: =IFERROR((HistoricalFS!L18-HistoricalFS!L24)/HistoricalFS!L6,0) -> 1.5734883 | N13: =IFERROR(AVERAGE(C13:L13),0) -> 1.5238203 | O13: =IFERROR(MEDIAN(C13:L13),0) -> 1.5167691
B14: EBT Margin | C14: =IFERROR(HistoricalFS!C28,0) -> 1.4029701 | D14: =IFERROR(HistoricalFS!D28,0) -> 1.4576731 | E14: =IFERROR(HistoricalFS!E28,0) -> 1.4301886 | F14: =IFERROR(HistoricalFS!F28,0) -> 1.4777264 | G14: =IFERROR(HistoricalFS!G28,0) -> 1.403547 | H14: =IFERROR(HistoricalFS!H28,0) -> 1.3778423 | I14: =IFERROR(HistoricalFS!I28,0) -> 1.5340902 | J14: =IFERROR(HistoricalFS!J28,0) -> 1.6196125 | ... L14: =IFERROR(HistoricalFS!L28,0) -> 1.5426145 | N14: =IFERROR(AVERAGE(C14:L14),0) -> 1.4852205 | O14: =IFERROR(MEDIAN(C14:L14),0) -> 1.4676997
B15: Net Profit Margin | C15: =IFERROR(HistoricalFS!C34,0) -> 1.3782326 | D15: =IFERROR(HistoricalFS!D34,0) -> 1.4301489 | E15: =IFERROR(HistoricalFS!E34,0) -> 1.3875776 | F15: =IFERROR(HistoricalFS!F34,0) -> 1.4960962 | G15: =IFERROR(HistoricalFS!G34,0) -> 1.3674147 | H15: =IFERROR(HistoricalFS!H34,0) -> 1.3430924 | I15: =IFERROR(HistoricalFS!I34,0) -> 1.4923411 | J15: =IFERROR(HistoricalFS!J34,0) -> 1.6031944 | ... L15: =IFERROR(HistoricalFS!L34,0) -> 1.5207188 | N15: =IFERROR(AVERAGE(C15:L15),0) -> 1.4600784 | O15: =IFERROR(MEDIAN(C15:L15),0) -> 1.461245
B17: SalesExpenses%Sales | C17: =IFERROR(HistoricalFS!C16,0) -> 0.19215326 | D17: =IFERROR(HistoricalFS!D16,0) -> 0.13879074 | E17: =IFERROR(HistoricalFS!E16,0) -> 0.14435762 | F17: =IFERROR(HistoricalFS!F16,0) -> 0.14156147 | G17: =IFERROR(HistoricalFS!G16,0) -> 0.1469439 | H17: =IFERROR(HistoricalFS!H16,0) -> 0.15110738 | I17: =IFERROR(HistoricalFS!I16,0) -> 0.13446808 | J17: =IFERROR(HistoricalFS!J16,0) -> 0.10371313 | ... L17: =IFERROR(HistoricalFS!L16,0) -> 0.11351653 | N17: =IFERROR(AVERAGE(C17:L17),0) -> 0.13651242 | O17: =IFERROR(MEDIAN(C17:L17),0) -> 0.1401761
B18: Depreciation%Sales | C18: =IFERROR(HistoricalFS!C25,0) -> 0.050515666 | D18: =IFERROR(HistoricalFS!D25,0) -> 0.046586153 | E18: =IFERROR(HistoricalFS!E25,0) -> 0.046564832 | F18: =IFERROR(HistoricalFS!F25,0) -> 0.060369992 | G18: =IFERROR(HistoricalFS!G25,0) -> 0.059009416 | H18: =IFERROR(HistoricalFS!H25,0) -> 0.03730489 | I18: =IFERROR(HistoricalFS!I25,0) -> 0.038360784 | J18: =IFERROR(HistoricalFS!J25,0) -> 0.043121379 | ... L18: =IFERROR(HistoricalFS!L25,0) -> 0.051496998 | N18: =IFERROR(AVERAGE(C18:L18),0) -> 0.048101571 | O18: =IFERROR(MEDIAN(C18:L18),0) -> 0.047135875
B19: OperatingIncome%Sales | C19: =IFERROR(C13,0) -> 1.4481369 | D19: =IFERROR(D13,0) -> 1.5019309 | E19: =IFERROR(E13,0) -> 1.478772 | F19: =IFERROR(F13,0) -> 1.5316074 | G19: =IFERROR(G13,0) -> 1.4521592 | H19: =IFERROR(H13,0) -> 1.4002321 | I19: =IFERROR(I13,0) -> 1.5599732 | J19: =IFERROR(J13,0) -> 1.6523723 | ... L19: =IFERROR(L13,0) -> 1.5734883 | N19: =IFERROR(AVERAGE(C19:L19),0) -> 1.5238203 | O19: =IFERROR(MEDIAN(C19:L19),0) -> 1.5167691
B21: Return on Capital Employed | C21: =IFERROR((HistoricalFS!C18-HistoricalFS!C24)/SUM(HistoricalFS!C48:C50),0) -> 1.3458562 | D21: =IFERROR((HistoricalFS!D18-HistoricalFS!D24)/SUM(HistoricalFS!D48:D50),0) -> 1.20974 | E21: =IFERROR((HistoricalFS!E18-HistoricalFS!E24)/SUM(HistoricalFS!E48:E50),0) -> 1.3735991 | F21: =IFERROR((HistoricalFS!F18-HistoricalFS!F24)/SUM(HistoricalFS!F48:F50),0) -> 1.1276416 | G21: =IFERROR((HistoricalFS!G18-HistoricalFS!G24)/SUM(HistoricalFS!G48:G50),0) -> 1.3962753 | H21: =IFERROR((HistoricalFS!H18-HistoricalFS!H24)/SUM(HistoricalFS!H48:H50),0) -> 1.7978504 | I21: =IFERROR((HistoricalFS!I18-HistoricalFS!I24)/SUM(HistoricalFS!I48:I50),0) -> 2.0195418 | J21: =IFERROR((HistoricalFS!J18-HistoricalFS!J24)/SUM(HistoricalFS!J48:J50),0) -> 2.114113 | ... L21: =IFERROR((HistoricalFS!L18-HistoricalFS!L24)/SUM(HistoricalFS!L48:L50),0) -> 1.8775161 | N21: =IFERROR(AVERAGE(C21:L21),0) -> 1.6188819 | O21: =IFERROR(MEDIAN(C21:L21),0) -> 1.5970628
B22: Retained Earnings% | C22: =IFERROR(HistoricalFS!C44,0) -> 0.99373128 | D22: =IFERROR(HistoricalFS!D44,0) -> 0.99350436 | E22: =IFERROR(HistoricalFS!E44,0) -> 0.99319666 | F22: =IFERROR(HistoricalFS!F44,0) -> 0.99452646 | G22: =IFERROR(HistoricalFS!G44,0) -> 0.98600726 | H22: =IFERROR(HistoricalFS!H44,0) -> 0.98099196 | I22: =IFERROR(HistoricalFS!I44,0) -> 0.98789405 | J22: =IFERROR(HistoricalFS!J44,0) -> 0.98777704 | ... L22: =IFERROR(HistoricalFS!L44,0) -> 0.98586549 | N22: =IFERROR(AVERAGE(C22:L22),0) -> 0.98905052 | O22: =IFERROR(MEDIAN(C22:L22),0) -> 0.98783555
B23: Return on Equity% | C23: =IFERROR(HistoricalFS!C33/SUM(HistoricalFS!C48:C49),0) -> 4.0924776 | D23: =IFERROR(HistoricalFS!D33/SUM(HistoricalFS!D48:D49),0) -> 2.8957241 | E23: =IFERROR(HistoricalFS!E33/SUM(HistoricalFS!E48:E49),0) -> 3.1741415 | F23: =IFERROR(HistoricalFS!F33/SUM(HistoricalFS!F48:F49),0) -> 2.8430236 | G23: =IFERROR(HistoricalFS!G33/SUM(HistoricalFS!G48:G49),0) -> 2.8821799 | H23: =IFERROR(HistoricalFS!H33/SUM(HistoricalFS!H48:H49),0) -> 2.8630811 | I23: =IFERROR(HistoricalFS!I33/SUM(HistoricalFS!I48:I49),0) -> 3.5230676 | J23: =IFERROR(HistoricalFS!J33/SUM(HistoricalFS!J48:J49),0) -> 3.9919842 | ... L23: =IFERROR(HistoricalFS!L33/SUM(HistoricalFS!L48:L49),0) -> 3.4552969 | N23: =IFERROR(AVERAGE(C23:L23),0) -> 3.3513106 | O23: =IFERROR(MEDIAN(C23:L23),0) -> 3.3147192
B24: Self Sustained Growth Rate | C24: =IFERROR('Ratio Analysis'!C22*'Ratio Analysis'!C23,0) -> 4.066823 | D24: =IFERROR('Ratio Analysis'!D22*'Ratio Analysis'!D23,0) -> 2.8769145 | E24: =IFERROR('Ratio Analysis'!E22*'Ratio Analysis'!E23,0) -> 3.1525468 | F24: =IFERROR('Ratio Analysis'!F22*'Ratio Analysis'!F23,0) -> 2.8274622 | G24: =IFERROR('Ratio Analysis'!G22*'Ratio Analysis'!G23,0) -> 2.8418503 | H24: =IFERROR('Ratio Analysis'!H22*'Ratio Analysis'!H23,0) -> 2.8086596 | I24: =IFERROR('Ratio Analysis'!I22*'Ratio Analysis'!I23,0) -> 3.4804176 | J24: =IFERROR('Ratio Analysis'!J22*'Ratio Analysis'!J23,0) -> 3.9431903 | ... L24: =IFERROR('Ratio Analysis'!L22*'Ratio Analysis'!L23,0) -> 3.4064579 | N24: =IFERROR(AVERAGE(C24:L24),0) -> 3.3147194 | O24: =IFERROR(MEDIAN(C24:L24),0) -> 3.2795024
B25: Interest Coverage Ratio | C25: =IFERROR((HistoricalFS!C18-HistoricalFS!C24)/HistoricalFS!C21,0) -> 32.062011 | D25: =IFERROR((HistoricalFS!D18-HistoricalFS!D24)/HistoricalFS!D21,0) -> 33.935914 | E25: =IFERROR((HistoricalFS!E18-HistoricalFS!E24)/HistoricalFS!E21,0) -> 30.437787 | F25: =IFERROR((HistoricalFS!F18-HistoricalFS!F24)/HistoricalFS!F21,0) -> 28.425745 | G25: =IFERROR((HistoricalFS!G18-HistoricalFS!G24)/HistoricalFS!G21,0) -> 29.872323 | H25: =IFERROR((HistoricalFS!H18-HistoricalFS!H24)/HistoricalFS!H21,0) -> 62.538805 | I25: =IFERROR((HistoricalFS!I18-HistoricalFS!I24)/HistoricalFS!I21,0) -> 60.270164 | J25: =IFERROR((HistoricalFS!J18-HistoricalFS!J24)/HistoricalFS!J21,0) -> 50.439149 | ... L25: =IFERROR((HistoricalFS!L18-HistoricalFS!L24)/HistoricalFS!L21,0) -> 50.965039 | N25: =IFERROR(AVERAGE(C25:L25),0) -> 42.77563 | O25: =IFERROR(MEDIAN(C25:L25),0) -> 41.372639
B27: Debtor Turnover Ratio | C27: =IFERROR(HistoricalFS!C6/HistoricalFS!C60,0) -> 9.6919966 | D27: =IFERROR(HistoricalFS!D6/HistoricalFS!D60,0) -> 9.9270163 | E27: =IFERROR(HistoricalFS!E6/HistoricalFS!E60,0) -> 13.349335 | F27: =IFERROR(HistoricalFS!F6/HistoricalFS!F60,0) -> 17.732181 | G27: =IFERROR(HistoricalFS!G6/HistoricalFS!G60,0) -> 16.402518 | H27: =IFERROR(HistoricalFS!H6/HistoricalFS!H60,0) -> 19.92084 | I27: =IFERROR(HistoricalFS!I6/HistoricalFS!I60,0) -> 29.471432 | J27: =IFERROR(HistoricalFS!J6/HistoricalFS!J60,0) -> 36.588119 | ... L27: =IFERROR(HistoricalFS!L6/HistoricalFS!L60,0) -> 47.212758 | N27: =IFERROR(AVERAGE(C27:L27),0) -> 24.184373 | O27: =IFERROR(MEDIAN(C27:L27),0) -> 18.82651
B28: Creditor Turnover Ratio | C28: =IFERROR(HistoricalFS!C6/HistoricalFS!C51,0) -> 2.1757736 | D28: =IFERROR(HistoricalFS!D6/HistoricalFS!D51,0) -> 2.2125526 | E28: =IFERROR(HistoricalFS!E6/HistoricalFS!E51,0) -> 2.5014063 | F28: =IFERROR(HistoricalFS!F6/HistoricalFS!F51,0) -> 2.359989 | G28: =IFERROR(HistoricalFS!G6/HistoricalFS!G51,0) -> 1.9277973 | H28: =IFERROR(HistoricalFS!H6/HistoricalFS!H51,0) -> 2.6397571 | I28: =IFERROR(HistoricalFS!I6/HistoricalFS!I51,0) -> 2.4979585 | J28: =IFERROR(HistoricalFS!J6/HistoricalFS!J51,0) -> 2.5408498 | ... L28: =IFERROR(HistoricalFS!L6/HistoricalFS!L51,0) -> 2.2766565 | N28: =IFERROR(AVERAGE(C28:L28),0) -> 2.3574887 | O28: =IFERROR(MEDIAN(C28:L28),0) -> 2.4010674
B29: Inventory Turnover | C29: =IFERROR(HistoricalFS!C6/HistoricalFS!C61,0) -> 4.527505 | D29: =IFERROR(HistoricalFS!D6/HistoricalFS!D61,0) -> 4.3503193 | E29: =IFERROR(HistoricalFS!E6/HistoricalFS!E61,0) -> 4.9806827 | F29: =IFERROR(HistoricalFS!F6/HistoricalFS!F61,0) -> 4.5002385 | G29: =IFERROR(HistoricalFS!G6/HistoricalFS!G61,0) -> 4.7023564 | H29: =IFERROR(HistoricalFS!H6/HistoricalFS!H61,0) -> 4.996666 | I29: =IFERROR(HistoricalFS!I6/HistoricalFS!I61,0) -> 4.4721348 | J29: =IFERROR(HistoricalFS!J6/HistoricalFS!J61,0) -> 4.6619688 | ... L29: =IFERROR(HistoricalFS!L6/HistoricalFS!L61,0) -> 4.9130957 | N29: =IFERROR(AVERAGE(C29:L29),0) -> 4.7006129 | O29: =IFERROR(MEDIAN(C29:L29),0) -> 4.6821626
B30: Fixed Asset Turnover | C30: =IFERROR(HistoricalFS!C6/HistoricalFS!C54,0) -> 1.220559 | D30: =IFERROR(HistoricalFS!D6/HistoricalFS!D54,0) -> 1.2824433 | E30: =IFERROR(HistoricalFS!E6/HistoricalFS!E54,0) -> 1.2670088 | F30: =IFERROR(HistoricalFS!F6/HistoricalFS!F54,0) -> 1.0391376 | G30: =IFERROR(HistoricalFS!G6/HistoricalFS!G54,0) -> 1.1524743 | H30: =IFERROR(HistoricalFS!H6/HistoricalFS!H54,0) -> 1.8303184 | I30: =IFERROR(HistoricalFS!I6/HistoricalFS!I54,0) -> 1.6597345 | J30: =IFERROR(HistoricalFS!J6/HistoricalFS!J54,0) -> 1.5399774 | ... L30: =IFERROR(HistoricalFS!L6/HistoricalFS!L54,0) -> 1.2903249 | N30: =IFERROR(AVERAGE(C30:L30),0) -> 1.3730104 | O30: =IFERROR(MEDIAN(C30:L30),0) -> 1.2863841
B31: Capital Turnover Ratio | C31: =IFERROR(HistoricalFS!C6/SUM(HistoricalFS!C48:C49),0) -> 2.9693665 | D31: =IFERROR(HistoricalFS!D6/SUM(HistoricalFS!D48:D49),0) -> 2.0247711 | E31: =IFERROR(HistoricalFS!E6/SUM(HistoricalFS!E48:E49),0) -> 2.2875416 | F31: =IFERROR(HistoricalFS!F6/SUM(HistoricalFS!F48:F49),0) -> 1.9002947 | G31: =IFERROR(HistoricalFS!G6/SUM(HistoricalFS!G48:G49),0) -> 2.1077585 | H31: =IFERROR(HistoricalFS!H6/SUM(HistoricalFS!H48:H49),0) -> 2.1317082 | I31: =IFERROR(HistoricalFS!I6/SUM(HistoricalFS!I48:I49),0) -> 2.3607657 | J31: =IFERROR(HistoricalFS!J6/SUM(HistoricalFS!J48:J49),0) -> 2.4900189 | ... L31: =IFERROR(HistoricalFS!L6/SUM(HistoricalFS!L48:L49),0) -> 2.2721472 | N31: =IFERROR(AVERAGE(C31:L31),0) -> 2.294147 | O31: =IFERROR(MEDIAN(C31:L31),0) -> 2.2798444
B33: (in days)
B34: Debtor Days | C34: =IFERROR(365/C27,0) -> 37.659939 | D34: =IFERROR(365/D27,0) -> 36.768349 | E34: =IFERROR(365/E27,0) -> 27.342187 | F34: =IFERROR(365/F27,0) -> 20.584045 | G34: =IFERROR(365/G27,0) -> 22.252681 | H34: =IFERROR(365/H27,0) -> 18.322521 | I34: =IFERROR(365/I27,0) -> 12.384875 | J34: =IFERROR(365/J27,0) -> 9.975916 | ... L34: =IFERROR(365/L27,0) -> 7.7309611 | N34: =IFERROR(AVERAGE(C34:L34),0) -> 20.180659 | O34: =IFERROR(MEDIAN(C34:L34),0) -> 19.453283
B35: Payable Days | C35: =IFERROR(365/C28,0) -> 167.75643 | D35: =IFERROR(365/D28,0) -> 164.96783 | E35: =IFERROR(365/E28,0) -> 145.91792 | F35: =IFERROR(365/F28,0) -> 154.66174 | G35: =IFERROR(365/G28,0) -> 189.33526 | H35: =IFERROR(365/H28,0) -> 138.2703 | I35: =IFERROR(365/I28,0) -> 146.11932 | J35: =IFERROR(365/J28,0) -> 143.65273 | ... L35: =IFERROR(365/L28,0) -> 160.32282 | N35: =IFERROR(AVERAGE(C35:L35),0) -> 156.04631 | O35: =IFERROR(MEDIAN(C35:L35),0) -> 152.06023
B36: Inventory Days | C36: =IFERROR(365/C29,0) -> 80.618353 | D36: =IFERROR(365/D29,0) -> 83.901887 | E36: =IFERROR(365/E29,0) -> 73.283126 | F36: =IFERROR(365/F29,0) -> 81.106812 | G36: =IFERROR(365/G29,0) -> 77.620658 | H36: =IFERROR(365/H29,0) -> 73.048709 | I36: =IFERROR(365/I29,0) -> 81.616503 | J36: =IFERROR(365/J29,0) -> 78.293102 | ... L36: =IFERROR(365/L29,0) -> 74.291246 | N36: =IFERROR(AVERAGE(C36:L36),0) -> 77.825253 | O36: =IFERROR(MEDIAN(C36:L36),0) -> 77.95688
B37: Cash Conversion Cycle | C37: =IFERROR(SUM(C34,C36)-C35,0) -> -49.478134 | D37: =IFERROR(SUM(D34,D36)-D35,0) -> -44.297593 | E37: =IFERROR(SUM(E34,E36)-E35,0) -> -45.292607 | F37: =IFERROR(SUM(F34,F36)-F35,0) -> -52.970883 | G37: =IFERROR(SUM(G34,G36)-G35,0) -> -89.461918 | H37: =IFERROR(SUM(H34,H36)-H35,0) -> -46.899069 | I37: =IFERROR(SUM(I34,I36)-I35,0) -> -52.117944 | J37: =IFERROR(SUM(J34,J36)-J35,0) -> -55.383708 | ... L37: =IFERROR(SUM(L34,L36)-L35,0) -> -78.300618 | N37: =IFERROR(AVERAGE(C37:L37),0) -> -58.040393 | O37: =IFERROR(MEDIAN(C37:L37),0) -> -52.544413
B39: CFO/Sales | C39: =IFERROR(HistoricalFS!C71/HistoricalFS!C6,0) -> 0.096388387 | D39: =IFERROR(HistoricalFS!D71/HistoricalFS!D6,0) -> 0.06509899 | E39: =IFERROR(HistoricalFS!E71/HistoricalFS!E6,0) -> 0.16069076 | F39: =IFERROR(HistoricalFS!F71/HistoricalFS!F6,0) -> 0.1442512 | G39: =IFERROR(HistoricalFS!G71/HistoricalFS!G6,0) -> 0.28327848 | H39: =IFERROR(HistoricalFS!H71/HistoricalFS!H6,0) -> 0.18191975 | I39: =IFERROR(HistoricalFS!I71/HistoricalFS!I6,0) -> 0.08910146 | J39: =IFERROR(HistoricalFS!J71/HistoricalFS!J6,0) -> 0.088583152 | ... L39: =IFERROR(HistoricalFS!L71/HistoricalFS!L6,0) -> 0.1510488 | N39: =IFERROR(AVERAGE(C39:L39),0) -> 0.13662332 | O39: =IFERROR(MEDIAN(C39:L39),0) -> 0.12506171
B40: CFO/Total Assets | C40: =IFERROR(HistoricalFS!C71/HistoricalFS!C65,0) -> 0.062769064 | D40: =IFERROR(HistoricalFS!D71/HistoricalFS!D65,0) -> 0.038440532 | E40: =IFERROR(HistoricalFS!E71/HistoricalFS!E65,0) -> 0.10884382 | F40: =IFERROR(HistoricalFS!F71/HistoricalFS!F65,0) -> 0.080950396 | G40: =IFERROR(HistoricalFS!G71/HistoricalFS!G65,0) -> 0.18173436 | H40: =IFERROR(HistoricalFS!H71/HistoricalFS!H65,0) -> 0.15714442 | I40: =IFERROR(HistoricalFS!I71/HistoricalFS!I65,0) -> 0.075975475 | J40: =IFERROR(HistoricalFS!J71/HistoricalFS!J65,0) -> 0.075379628 | ... L40: =IFERROR(HistoricalFS!L71/HistoricalFS!L65,0) -> 0.11825542 | N40: =IFERROR(AVERAGE(C40:L40),0) -> 0.098348969 | O40: =IFERROR(MEDIAN(C40:L40),0) -> 0.082473491
B41: CFO/Total Debt | C41: =IFERROR(HistoricalFS!C71/HistoricalFS!C50,0) -> 0.13039121 | D41: =IFERROR(HistoricalFS!D71/HistoricalFS!D50,0) -> 0.087071588 | E41: =IFERROR(HistoricalFS!E71/HistoricalFS!E50,0) -> 0.25130827 | F41: =IFERROR(HistoricalFS!F71/HistoricalFS!F50,0) -> 0.17337774 | G41: =IFERROR(HistoricalFS!G71/HistoricalFS!G50,0) -> 0.50085846 | H41: =IFERROR(HistoricalFS!H71/HistoricalFS!H50,0) -> 0.58735041 | I41: =IFERROR(HistoricalFS!I71/HistoricalFS!I50,0) -> 0.25541643 | J41: =IFERROR(HistoricalFS!J71/HistoricalFS!J50,0) -> 0.23312099 | ... L41: =IFERROR(HistoricalFS!L71/HistoricalFS!L50,0) -> 0.37956075 | N41: =IFERROR(AVERAGE(C41:L41),0) -> 0.28425205 | O41: =IFERROR(MEDIAN(C41:L41),0) -> 0.24768643

Sheet Forecasting
B2: ='Data Sheet'!$B$1&" - "&'Data Sheet'!A17&" Forecasting" -> TATA STEEL LTD - Sales Forecasting | G2: ='Data Sheet'!$B$1&" - "&'Data Sheet'!A34&" Forecasting" -> TATA STEEL LTD - EBITDA Forecasting | L2: ='Data Sheet'!$B$1&" - "&HistoricalFS!B38&" Forecasting" -> TATA STEEL LTD - EPS Forecasting
B3: Year Weight | C3: Year | D3: Sales | E3: Sales Growth | G3: Year Weight | H3: Year | I3: Sales | J3: Sales Growth | L3: Year Weight | M3: Year | N3: Sales | O3: Sales Growth
B4: 1 | C4: ='Data Sheet'!$B$16 -> 42825 | D4: {=TRANSPOSE('Data Sheet'!B17:K17)} -> 112299.42 | G4: 1 | H4: ='Data Sheet'!$B$16 -> 42825 | I4: {=TRANSPOSE('Data Sheet'!B34:K34)} -> 9282.29 | L4: 1 | M4: ='Data Sheet'!$B$16 -> 42825 | N4: {=TRANSPOSE(HistoricalFS!C38:L38)} -> 137.3797
B5: =B4+1 -> 2 | C5: =C4+365 -> 43190 | D5: 123249.07 | E5: =D5/D4-1 -> 0.097504065 | G5: =G4+1 -> 2 | H5: =H4+365 -> 43190 | I5: 28023.1 | J5: =I5/I4-1 -> 2.0189856 | L5: =L4+1 -> 2 | M5: =M4+365 -> 43190 | N5: 156.47372 | O5: =N5/N4-1 -> 0.13898721
B6: =B5+1 -> 3 | C6: =C5+365 -> 43555 | D6: 157668.99 | E6: =D6/D5-1 -> 0.27927124 | G6: =G5+1 -> 3 | H6: =H5+365 -> 43555 | I6: 31938.69 | J6: =I6/I5-1 -> 0.13972723 | L6: =L5+1 -> 3 | M6: =M5+365 -> 43555 | N6: 194.21207 | O6: =N6/N5-1 -> 0.24118012
B7: =B6+1 -> 4 | C7: =C6+365 -> 43920 | D7: 139816.65 | E7: =D7/D6-1 -> -0.1132267 | G7: =G6+1 -> 4 | H7: =H6+365 -> 43920 | I7: 14962.32 | J7: =I7/I6-1 -> -0.53152994 | L7: =L6+1 -> 4 | M7: =M6+365 -> 43920 | N7: 185.69109 | O7: =N7/N6-1 -> -0.043874621
B8: =B7+1 -> 5 | C8: =C7+365 -> 44285 | D8: 156477.4 | E8: =D8/D7-1 -> 0.11916142 | G8: =G7+1 -> 5 | H8: =H7+365 -> 44285 | I8: 29984.47 | J8: =I8/I7-1 -> 1.0039987 | L8: =L7+1 -> 5 | M8: =M7+365 -> 44285 | N8: 178.81604 | O8: =N8/N7-1 -> -0.037024122
B9: =B8+1 -> 6 | C9: =C8+365 -> 44650 | D9: 243959.17 | E9: =D9/D8-1 -> 0.55906968 | G9: =G8+1 -> 6 | H9: =H8+365 -> 44650 | I9: 63194.55 | J9: =I9/I8-1 -> 1.107576 | L9: =L8+1 -> 6 | M9: =M8+365 -> 44650 | N9: 268.28765 | O9: =N9/N8-1 -> 0.5003556
B10: =B9+1 -> 7 | C10: =C9+365 -> 45015 | D10: 243352.69 | E10: =D10/D9-1 -> -0.0024859898 | G10: =G9+1 -> 7 | H10: =H9+365 -> 45015 | I10: 34554.07 | J10: =I10/I9-1 -> -0.45321123 | L10: =L9+1 -> 7 | M10: =M9+365 -> 45015 | N10: 297.15273 | O10: =N10/N9-1 -> 0.10759004
B11: =B10+1 -> 8 | C11: =C10+365 -> 45380 | D11: 229170.78 | E11: =D11/D10-1 -> -0.058277186 | G11: =G10+1 -> 8 | H11: =H10+365 -> 45380 | I11: 16714.86 | J11: =I11/I10-1 -> -0.51626943 | L11: =L10+1 -> 8 | M11: =M10+365 -> 45380 | N11: 294.31273 | O11: =N11/N10-1 -> -0.0095573681
B12: =B11+1 -> 9 | C12: =C11+365 -> 45745 | D12: 218542.51 | E12: =D12/D11-1 -> -0.046377073 | G12: =G11+1 -> 9 | H12: =H11+365 -> 45745 | I12: 26421.88 | J12: =I12/I11-1 -> 0.58074193 | L12: =L11+1 -> 9 | M12: =M11+365 -> 45745 | N12: 276.94722 | O12: =N12/N11-1 -> -0.059003613
B13: =B12+1 -> 10 | C13: =C12+365 -> 46110 | D13: 232139.94 | E13: =D13/D12-1 -> 0.062218696 | G13: =G12+1 -> 10 | H13: =H12+365 -> 46110 | I13: 34998.31 | J13: =I13/I12-1 -> 0.32459575 | L13: =L12+1 -> 10 | M13: =M12+365 -> 46110 | N13: 282.78893 | O13: =N13/N12-1 -> 0.021093229
B14: =B13+1 -> 11 | C14: =C13+365 -> 46475 | D14: =FORECAST(B14,$D$4:$D$13,$B$4:$B$13) -> 269041.58 | E14: =D14/D13-1 -> 0.15896292 | G14: =G13+1 -> 11 | H14: =H13+365 -> 46475 | I14: =FORECAST(G14,$I$4:$I$13,$G$4:$G$13) -> 36877.515 | J14: =I14/I13-1 -> 0.053694155 | L14: =L13+1 -> 11 | M14: =M13+365 -> 46475 | N14: =FORECAST(L14,$N$4:$N$13,$L$4:$L$13) -> 329.75143 | O14: =N14/N13-1 -> 0.16606911
B15: =B14+1 -> 12 | C15: =C14+365 -> 46840 | D15: =FORECAST(B15,$D$4:$D$13,$B$4:$B$13) -> 284200.48 | E15: =D15/D14-1 -> 0.056344058 | G15: =G14+1 -> 12 | H15: =H14+365 -> 46840 | I15: =FORECAST(G15,$I$4:$I$13,$G$4:$G$13) -> 38308.435 | J15: =I15/I14-1 -> 0.038801967 | L15: =L14+1 -> 12 | M15: =M14+365 -> 46840 | N15: =FORECAST(L15,$N$4:$N$13,$L$4:$L$13) -> 348.39602 | O15: =N15/N14-1 -> 0.056541346
B16: =B15+1 -> 13 | C16: =C15+365 -> 47205 | D16: =FORECAST(B16,$D$4:$D$13,$B$4:$B$13) -> 299359.37 | E16: =D16/D15-1 -> 0.053338737 | G16: =G15+1 -> 13 | H16: =H15+365 -> 47205 | I16: =FORECAST(G16,$I$4:$I$13,$G$4:$G$13) -> 39739.355 | J16: =I16/I15-1 -> 0.037352613 | L16: =L15+1 -> 13 | M16: =M15+365 -> 47205 | N16: =FORECAST(L16,$N$4:$N$13,$L$4:$L$13) -> 367.04061 | O16: =N16/N15-1 -> 0.053515507
B17: =B16+1 -> 14 | C17: =C16+365 -> 47570 | D17: =FORECAST(B17,$D$4:$D$13,$B$4:$B$13) -> 314518.27 | E17: =D17/D16-1 -> 0.050637782 | G17: =G16+1 -> 14 | H17: =H16+365 -> 47570 | I17: =FORECAST(G17,$I$4:$I$13,$G$4:$G$13) -> 41170.275 | J17: =I17/I16-1 -> 0.036007633 | L17: =L16+1 -> 14 | M17: =M16+365 -> 47570 | N17: =FORECAST(L17,$N$4:$N$13,$L$4:$L$13) -> 385.6852 | O17: =N17/N16-1 -> 0.050797076
B18: =B17+1 -> 15 | C18: =C17+365 -> 47935 | D18: =FORECAST(B18,$D$4:$D$13,$B$4:$B$13) -> 329677.16 | E18: =D18/D17-1 -> 0.048197183 | G18: =G17+1 -> 15 | H18: =H17+365 -> 47935 | I18: =FORECAST(G18,$I$4:$I$13,$G$4:$G$13) -> 42601.195 | J18: =I18/I17-1 -> 0.034756147 | L18: =L17+1 -> 15 | M18: =M17+365 -> 47935 | N18: =FORECAST(L18,$N$4:$N$13,$L$4:$L$13) -> 404.32979 | O18: =N18/N17-1 -> 0.04834147

Sheet Data Sheet
A1: COMPANY NAME | B1: TATA STEEL LTD | E1: =IF(B2<>B3, "A NEW VERSION OF THE WORKSHEET IS AVAILABLE", "")
A2: LATEST VERSION | B2: 2.1 | E2: PLEASE DO NOT MAKE ANY CHANGES TO THIS SHEET
A3: CURRENT VERSION | B3: 2.1
A5: META
A6: Number of shares | B6: =IF(B9>0, B9/B8, 0) -> 1249.093
A7: Face Value | B7: 1
A8: Current Price | B8: 184.15
A9: Market Capitalization | B9: 230020.47
A15: PROFIT & LOSS
A16: Report Date | B16: 42825 | C16: 43190 | D16: 43555 | E16: 43921 | F16: 44286 | G16: 44651 | H16: 45016 | I16: 45382 | J16: 45747 | K16: 46112
A17: Sales | B17: 112299.42 | C17: 123249.07 | D17: 157668.99 | E17: 139816.65 | F17: 156477.4 | G17: 243959.17 | H17: 243352.69 | I17: 229170.78 | J17: 218542.51 | K17: 232139.94
A18: Raw Material Cost | B18: 43843.03 | C18: 46137.01 | D18: 60877.05 | E18: 58039.99 | F18: 55100.81 | G18: 91076.61 | H18: 116597.19 | I18: 97506.39 | J18: 95097.3 | K18: 92628.07
A19: Change in Inventory | B19: 4538.13 | C19: -99.31 | D19: 96.71 | E19: 565.24 | F19: -1516.77 | G19: 7597.87 | H19: 3358.89 | I19: -4409.35 | J19: 96.65 | K19: -989.62
A20: Power and Fuel | B20: 5220.83 | C20: 4440.43 | D20: 5316.56 | E20: 5319.92 | F20: 5708.42 | G20: 8028.29 | H20: 9526.91 | I20: 16612.61 | J20: 13124.85 | K20: 14333.15
A21: Other Mfr. Exp | B21: 15799.14 | C21: 16955.79 | D21: 20734.28 | E21: 21232.69 | F21: 20744.93 | G21: 28834.06 | H21: 33144.83 | I21: 40116.91 | J21: 38700.5 | K21: 37485.96
A22: Employee Cost | B22: 17252.22 | C22: 17077.51 | D22: 18758.87 | E22: 18533.58 | F22: 19908.81 | G22: 23264.1 | H22: 22419.32 | I22: 24509.58 | J22: 24888.99 | K22: 25998.98
A23: Selling and admin | B23: 13772.32 | C23: 14423.87 | D23: 16917.14 | E23: 15599.07 | F23: 17509.77 | G23: 27445.67 | H23: 25519.92 | I23: 14453.57 | J23: 12137.26 | K23: 13348.99
A24: Other Expenses | B24: 7806.38 | C24: 2681.96 | D24: 5843.58 | E24: 4193.58 | F24: 5483.63 | G24: 9418.36 | H24: 7203.25 | I24: 9314.45 | J24: 9391.81 | K24: 13002.73
A25: Other Income | B25: -3789.11 | C25: 10898.41 | D25: 1524.31 | E25: -2883.63 | F25: 179.78 | G25: 1299.99 | H25: 1568.86 | I25: -6005.23 | J25: 876.7 | K25: 737.82
A26: Depreciation | B26: 5672.88 | C26: 5741.7 | D26: 7341.83 | E26: 8440.73 | F26: 9233.64 | G26: 9100.87 | H26: 9335.2 | I26: 9882.16 | J26: 10421.33 | K26: 11954.51
A27: Interest | B27: 5072.2 | C27: 5454.74 | D27: 7660.1 | E27: 7533.46 | F27: 7606.71 | G27: 5462.2 | H27: 6298.7 | I27: 7507.57 | J27: 7340.95 | K27: 7167.06
... A31: Dividend Amount | B31: 970.24 | C31: 1144.95 | D31: 1488.42 | E31: 1144.95 | F31: 2994.02 | G31: 6228.17 | H31: 4396.46 | I31: 4490.78 | J31: 4490.78 | K31: 4989.76
A32: Effective tax rate | B32: =B29/B28 -> -1.9977635 | C32: =C29/C28 -> 0.16050647 | D32: =D29/D28 -> 0.42412724 | E32: =E29/E28 -> 1.8414709 | F32: =F29/F28 -> 0.4084099 | G32: =G29/G28 -> 0.16878515 | H32: =H29/H28 -> 0.557154 | I32: =I29/I28 -> -3.2802431 | ... K32: =K29/K28 -> 0.31830225
A34: EBITDA | B34: =B26+B27+B29+B30 -> 9282.29 | C34: =C26+C27+C29+C30 -> 28023.1 | D34: =D26+D27+D29+D30 -> 31938.69 | E34: =E26+E27+E29+E30 -> 14962.32 | F34: =F26+F27+F29+F30 -> 29984.47 | G34: =G26+G27+G29+G30 -> 63194.55 | H34: =H26+H27+H29+H30 -> 34554.07 | I34: =I26+I27+I29+I30 -> 16714.86 | ... K34: =K26+K27+K29+K30 -> 34998.31
A40: Quarters
A41: Report Date | B41: 45382 | C41: 45473 | D41: 45565 | E41: 45657 | F41: 45747 | G41: 45838 | H41: 45930 | I41: 46022 | J41: 46112 | K41: 46203
A42: Sales | B42: 58687.31 | C42: 54771.39 | D42: 53904.71 | E42: 53648.3 | F42: 56218.11 | G42: 53178.12 | H42: 58689.29 | I42: 57002.4 | J42: 63270.13 | K42: 60794.29
A43: Expenses | B43: 52086.68 | C43: 48076.92 | D43: 47788.92 | E43: 47744.81 | F43: 49658.89 | G43: 45750.58 | H43: 49792.75 | I43: 48802.7 | J43: 53441.47 | K43: 51529.95
A44: Other Income | B44: -381.56 | C44: -5.51 | D44: 616.68 | E44: 141.82 | F44: 149.19 | G44: 236.27 | H44: -6.11 | I44: 465.17 | J44: 42.49 | K44: -16.65
A45: Depreciation | B45: 2567.95 | C45: 2535.43 | D45: 2596.74 | E45: 2569.19 | F45: 2719.97 | G45: 2744.3 | H45: 2893 | I45: 3048.81 | J45: 3268.4 | K45: 3639.65
A46: Interest | B46: 1842.25 | C46: 1776.71 | D46: 1971.4 | E46: 1804.09 | F46: 1788.75 | G46: 1852.43 | H46: 1774.96 | I46: 1747.29 | J46: 1792.38 | K46: 1770.51
A47: Profit before tax | B47: 1808.87 | C47: 2376.82 | D47: 2164.33 | E47: 1672.03 | F47: 2199.69 | G47: 3067.08 | H47: 4222.47 | I47: 3868.77 | J47: 4810.37 | K47: 3837.53
A48: Tax | B48: 1254.31 | C48: 1458.25 | D48: 1405.49 | E48: 1376.54 | F48: 998.81 | G48: 1059.72 | H48: 1039.38 | I48: 1138.4 | J48: 1845.37 | K48: 1452.29
A49: Net profit | B49: 611.48 | C49: 959.61 | D49: 833.45 | E49: 326.64 | F49: 1300.81 | G49: 2077.68 | H49: 3101.75 | I49: 2688.7 | J49: 2925.74 | K49: 2318.35
A50: Operating Profit | B50: 6600.63 | C50: 6694.47 | D50: 6115.79 | E50: 5903.49 | F50: 6559.22 | G50: 7427.54 | H50: 8896.54 | I50: 8199.7 | J50: 9828.66 | K50: 9264.34
A55: BALANCE SHEET
A56: Report Date | B56: 42825 | C56: 43190 | D56: 43555 | E56: 43921 | F56: 44286 | G56: 44651 | H56: 45016 | I56: 45382 | J56: 45747 | K56: 46112
A57: Equity Share Capital | B57: 970.24 | C57: 1144.95 | D57: 1144.94 | E57: 1144.95 | F57: 1197.61 | G57: 1221.21 | H57: 1221.24 | I57: 1247.44 | J57: 1247.44 | K57: 1247.44
A58: Reserves | B58: 36849.08 | C58: 59725.67 | D58: 67780.14 | E58: 72431.35 | F58: 73041.16 | G58: 113221.83 | H58: 101860.86 | I58: 90788.32 | J58: 89922.19 | K58: 100920.21
A59: Borrowings | B59: 83014.49 | C59: 92147.05 | D59: 100816.22 | E59: 116328.2 | F59: 88501.41 | G59: 75561.35 | H59: 84893.05 | I59: 87082.12 | J59: 94801.05 | K59: 92381.68
...

Sheet Cash Flow Data
B2: 42064 | C2: 42430 | D2: 42795 | E2: 43160 | F2: 43525 | G2: 43891 | H2: 44256 | I2: 44621 | J2: 44986 | K2: 45352 | L2: 45717 | M2: 46082
B3: Cash from Operating Activity - | C3: 11880 | D3: 11455 | E3: 10824 | F3: 8023 | G3: 25336 | H3: 20169 | I3: 44327 | J3: 44381 | K3: 21683 | L3: 20301 | M3: 23138 | N3: 35064
B4: Profit from operations | C4: 13955 | D4: 6824 | E4: 17581 | F4: 20187 | G4: 27840 | H4: 18078 | I4: 28540 | J4: 65900 | K4: 30908 | L4: 22237 | M4: 23929 | N4: 34219
B5: Receivables | C5: 1442 | D5: 0 | E5: 0 | F5: 0 | G5: 0 | H5: 0 | I5: 0 | J5: 0 | K5: 0 | L5: 0 | M5: 0 | N5: 0
B6: Inventory | C6: -485 | D6: 5618 | E6: -8243 | F6: -1595 | G6: -1069 | H6: 1562 | I6: 46 | J6: -16917 | K6: -4031 | L6: 5566 | M6: 4776 | N6: 1290
B7: Payables | C7: -605 | D7: 0 | E7: 0 | F7: 0 | G7: 0 | H7: 0 | I7: 0 | J7: 0 | K7: 0 | L7: 0 | M7: 0 | N7: 0
B8: Other WC items | C8: 0 | D8: 548 | E8: 3329 | F8: -7680 | G8: 3659 | H8: 2634 | I8: 16446 | J8: 7299 | K8: 325 | L8: -2182 | M8: -2569 | N8: 4152
B9: Working capital changes | C9: 351 | D9: 6166 | E9: -4914 | F9: -9276 | G9: 2591 | H9: 4196 | I9: 16491 | J9: -9618 | K9: -3706 | L9: 3384 | M9: 2207 | N9: 5442
B10: Direct taxes | C10: -2427 | D10: -1534 | E10: -1843 | F10: -2888 | G10: -5094 | H10: -2106 | I10: -704 | J10: -11902 | K10: -5519 | L10: -5320 | M10: -2998 | N10: -4597
B11: Cash from Investing Activity - | C11: -9021 | D11: -8794 | E11: -9490 | F11: -11730 | G11: -29176 | H11: -14012 | I11: -9437 | J11: -10905 | K11: -18179 | L11: -14253 | M11: -13611 | N11: -14397
B12: Fixed assets purchased | C12: -13492 | D12: -10163 | E12: -7716 | F12: -7478 | G12: -9091 | H12: -10398 | I12: -6979 | J12: -10522 | K12: -14142 | L12: -18207 | M12: -15671 | N12: -14559
B13: Fixed assets sold | C13: 1444 | D13: 231 | E13: 289 | F13: 179 | G13: 467 | H13: 386 | I13: 445 | J13: 569 | K13: 328 | L13: 475 | M13: 1264 | N13: 1401
B14: Investments purchased | C14: 1531 | D14: -3796 | E14: -861 | F14: -8641 | G14: -490 | H14: -828 | I14: -3631 | J14: -1153 | K14: -326 | L14: -4 | M14: -393 | N14: -553
... B32: CFO/OP | C32: 4.2 | D32: -20.78 | E32: 0.96 | F32: 0.51 | G32: 1.04 | H32: 1.28 | I32: 1.48 | J32: 0.89 | K32: 0.84 | L32: 1.15 | M32: 1.03 | N32: 1.15
